Workbook

Sheet サマリー
A1: 資金計画サマリー — シナリオ別（EEFUL HD単体・百万円・2026/9〜2027/12）
A2: 各シナリオシートのモード（現行／最小化）・実行フラグ、前提シートの入力値を変えると自動で再計算。緑字＝他シート参照。初期設定は全シナリオ「最小化」モード
A4: シナリオ | B4: モード | C4: 実行案件 | D4: 総支出（案件・16ヶ月） | E4: 最低残高 | F4: 最低残高の月 | G4: 初めて安全水準を割る月 | H4: 必要調達額（2027/12まで） | I4: 2026/11までの不足 | J4: 2027/1までの不足 | K4: 2027/3までの不足 | L4: 2027/12 期末現預金 | M4: 年換算売上（オーガニック＋実行案件） | N4: 年換算 調整後EBITDA（現状） | O4: 年換算 調整後EBITDA（改善後） | P4: 承継・残置負債 | Q4: Net Debt Capacity 2026/12 | R4: Net Debt Capacity 2027/12 | S4: 2027/12 有利子負債（調達前）
A5: S1 基本（確定4件＋HT実行済） | B5: =S1!$B$3 -> 最小化 | C5: メディプロ、ヒューマンアイ、シルバーメディカル、クレッシェンド | D5: =S1!$B$46 -> 253.7 | E5: =S1!$B$47 -> 24.6 | F5: =S1!$B$48 -> 2027/12 | G5: =S1!$B$49 -> 2026/12 | H5: =S1!$B$50 -> 75.4 | I5: =S1!$B$51 -> 0 | J5: =S1!$B$52 -> 8.4 | K5: =S1!$B$53 -> 30.4 | L5: =S1!$B$54 -> 24.6 | M5: =S1!$B$55 -> 2435 | N5: =S1!$B$56 -> 83 | O5: =S1!$B$57 -> 140 | P5: =S1!$B$58 -> 127.85 | Q5: =S1!$B$59 -> 348.2 | R5: =S1!$B$60 -> 372.5 | S5: =S1!$B$61 -> 515.1
A6: S2 基本＋ワイズケア | B6: =S2!$B$3 -> 最小化 | C6: メディプロ、ヒューマンアイ、シルバーメディカル、クレッシェンド、ワイズケア | D6: =S2!$B$46 -> 389.7 | E6: =S2!$B$47 -> -111.4 | F6: =S2!$B$48 -> 2027/12 | G6: =S2!$B$49 -> 2026/11 | H6: =S2!$B$50 -> 211.4 | I6: =S2!$B$51 -> 6.4 | J6: =S2!$B$52 -> 144.4 | K6: =S2!$B$53 -> 166.4 | L6: =S2!$B$54 -> -111.4 | M6: =S2!$B$55 -> 2920 | N6: =S2!$B$56 -> 121 | O6: =S2!$B$57 -> 206 | P6: =S2!$B$58 -> 127.85 | Q6: =S2!$B$59 -> 375.2 | R6: =S2!$B$60 -> 399.5 | S6: =S2!$B$61 -> 595.1
A7: S3 基本＋エーステイスト | B7: =S3!$B$3 -> 最小化 | C7: メディプロ、ヒューマンアイ、シルバーメディカル、クレッシェンド、エーステイスト | D7: =S3!$B$46 -> 328.2 | E7: =S3!$B$47 -> -49.9 | F7: =S3!$B$48 -> 2027/12 | G7: =S3!$B$49 -> 2026/12 | H7: =S3!$B$50 -> 149.9 | I7: =S3!$B$51 -> 0 | J7: =S3!$B$52 -> 82.9 | K7: =S3!$B$53 -> 104.9 | L7: =S3!$B$54 -> -49.9 | M7: =S3!$B$55 -> 3111 | N7: =S3!$B$56 -> 101 | O7: =S3!$B$57 -> 183 | P7: =S3!$B$58 -> 188.25 | Q7: =S3!$B$59 -> 380.4 | R7: =S3!$B$60 -> 404.6 | S7: =S3!$B$61 -> 575.5
A8: S4 基本＋ワイズ＋エース | B8: =S4!$B$3 -> 最小化 | C8: メディプロ、ヒューマンアイ、シルバーメディカル、クレッシェンド、ワイズケア、エーステイスト | D8: =S4!$B$46 -> 464.2 | E8: =S4!$B$47 -> -185.9 | F8: =S4!$B$48 -> 2027/12 | G8: =S4!$B$49 -> 2026/11 | H8: =S4!$B$50 -> 285.9 | I8: =S4!$B$51 -> 11.15 | J8: =S4!$B$52 -> 218.9 | K8: =S4!$B$53 -> 240.9 | L8: =S4!$B$54 -> -185.9 | M8: =S4!$B$55 -> 3596 | N8: =S4!$B$56 -> 139 | O8: =S4!$B$57 -> 249 | P8: =S4!$B$58 -> 188.25 | Q8: =S4!$B$59 -> 407.3 | R8: =S4!$B$60 -> 431.5 | S8: =S4!$B$61 -> 655.5
A9: S5 全件（＋日本経営C＋セレサ） | B9: =S5!$B$3 -> 最小化 | C9: メディプロ、ヒューマンアイ、クレッシェンド、ワイズケア、エーステイスト、日本経営センター、セレサ、シルバーメディカル | D9: =S5!$B$46 -> 614.3 | E9: =S5!$B$47 -> -336 | F9: =S5!$B$48 -> 2027/12 | G9: =S5!$B$49 -> 2026/11 | H9: =S5!$B$50 -> 436 | I9: =S5!$B$51 -> 11.15 | J9: =S5!$B$52 -> 311.4 | K9: =S5!$B$53 -> 391 | L9: =S5!$B$54 -> -336 | M9: =S5!$B$55 -> 4114 | N9: =S5!$B$56 -> 159 | O9: =S5!$B$57 -> 289 | P9: =S5!$B$58 -> 221.15 | Q9: =S5!$B$59 -> 402.7 | R9: =S5!$B$60 -> 439.6 | S9: =S5!$B$61 -> 688.4
A13: 参考：モード別の必要調達額（モデル計算値・値貼付）
A14: シナリオ | B14: 総支出（現行） | C14: 必要調達額（現行） | D14: 総支出（最小化） | E14: 必要調達額（最小化） | F14: 初回不足月（最小化） | G14: 年換算売上 | H14: EBITDA現状／改善後
A15: S1 基本（確定4件＋HT実行済） | B15: 367.7 | C15: 189 | D15: 253.7 | E15: 75 | F15: 26/12 | G15: 2435 | H15: 83 / 140
A16: S2 基本＋ワイズケア | B16: 633.7 | C16: 455 | D16: 389.7 | E16: 211 | F16: 26/11 | G16: 2920 | H16: 121 / 206
A17: S3 基本＋エーステイスト | B17: 442.2 | C17: 264 | D17: 328.2 | E17: 150 | F17: 26/12 | G17: 3111 | H17: 101 / 183
A18: S4 基本＋ワイズ＋エース | B18: 708.2 | C18: 530 | D18: 464.2 | E18: 286 | F18: 26/11 | G18: 3596 | H18: 139 / 249
A19: S5 全件（＋日本経営C＋セレサ） | B19: 879.9 | C19: 702 | D19: 614.3 | E19: 436 | F19: 26/11 | G19: 4114 | H19: 159 / 289
A21: 期末現預金の月次推移（シナリオ別・各シートのモードに連動）
A22: シナリオ | D22: 2026/9 | E22: 2026/10 | F22: 2026/11 | G22: 2026/12 | H22: 2027/1 | I22: 2027/2 | J22: 2027/3 | K22: 2027/4 | L22: 2027/5 | M22: 2027/6 | N22: 2027/7 | O22: 2027/8 | P22: 2027/9 | Q22: 2027/10 | R22: 2027/11 | S22: 2027/12
A23: S1 基本（確定4件＋HT実行済） | D23: =S1!C31 -> 329.3 | E23: =S1!D31 -> 304.1 | F23: =S1!E31 -> 229.6 | G23: =S1!F31 -> 96.6 | H23: =S1!G31 -> 91.6 | I23: =S1!H31 -> 86.6 | J23: =S1!I31 -> 69.6 | K23: =S1!J31 -> 64.6 | ... S23: =S1!R31 -> 24.6
A24: S2 基本＋ワイズケア | D24: =S2!C31 -> 329.3 | E24: =S2!D31 -> 295.4 | F24: =S2!E31 -> 93.6 | G24: =S2!F31 -> -39.4 | H24: =S2!G31 -> -44.4 | I24: =S2!H31 -> -49.4 | J24: =S2!I31 -> -66.4 | K24: =S2!J31 -> -71.4 | ... S24: =S2!R31 -> -111.4
A25: S3 基本＋エーステイスト | D25: =S3!C31 -> 329.3 | E25: =S3!D31 -> 301.35 | F25: =S3!E31 -> 224.85 | G25: =S3!F31 -> 22.1 | H25: =S3!G31 -> 17.1 | I25: =S3!H31 -> 12.1 | J25: =S3!I31 -> -4.9 | K25: =S3!J31 -> -9.9 | ... S25: =S3!R31 -> -49.9
A26: S4 基本＋ワイズ＋エース | D26: =S4!C31 -> 329.3 | E26: =S4!D31 -> 292.65 | F26: =S4!E31 -> 88.85 | G26: =S4!F31 -> -113.9 | H26: =S4!G31 -> -118.9 | I26: =S4!H31 -> -123.9 | J26: =S4!I31 -> -140.9 | K26: =S4!J31 -> -145.9 | ... S26: =S4!R31 -> -185.9
A27: S5 全件（＋日本経営C＋セレサ） | D27: =S5!C31 -> 329.3 | E27: =S5!D31 -> 292.65 | F27: =S5!E31 -> 88.85 | G27: =S5!F31 -> -118.65 | H27: =S5!G31 -> -211.4 | I27: =S5!H31 -> -218.5 | J27: =S5!I31 -> -291 | K27: =S5!J31 -> -296 | ... S27: =S5!R31 -> -336
A28: 安全水準 | D28: =前提!$B$4 -> 100 | E28: =前提!$B$4 -> 100 | F28: =前提!$B$4 -> 100 | G28: =前提!$B$4 -> 100 | H28: =前提!$B$4 -> 100 | I28: =前提!$B$4 -> 100 | J28: =前提!$B$4 -> 100 | K28: =前提!$B$4 -> 100 | ... S28: =前提!$B$4 -> 100
A30: 必要調達額（累計不足額）の月次推移
A31: シナリオ | D31: 2026/9 | E31: 2026/10 | F31: 2026/11 | G31: 2026/12 | H31: 2027/1 | I31: 2027/2 | J31: 2027/3 | K31: 2027/4 | L31: 2027/5 | M31: 2027/6 | N31: 2027/7 | O31: 2027/8 | P31: 2027/9 | Q31: 2027/10 | R31: 2027/11 | S31: 2027/12
A32: S1 基本（確定4件＋HT実行済） | D32: =S1!C33 -> 0 | E32: =S1!D33 -> 0 | F32: =S1!E33 -> 0 | G32: =S1!F33 -> 3.4 | H32: =S1!G33 -> 8.4 | I32: =S1!H33 -> 13.4 | J32: =S1!I33 -> 30.4 | K32: =S1!J33 -> 35.4 | ... S32: =S1!R33 -> 75.4
A33: S2 基本＋ワイズケア | D33: =S2!C33 -> 0 | E33: =S2!D33 -> 0 | F33: =S2!E33 -> 6.4 | G33: =S2!F33 -> 139.4 | H33: =S2!G33 -> 144.4 | I33: =S2!H33 -> 149.4 | J33: =S2!I33 -> 166.4 | K33: =S2!J33 -> 171.4 | ... S33: =S2!R33 -> 211.4
A34: S3 基本＋エーステイスト | D34: =S3!C33 -> 0 | E34: =S3!D33 -> 0 | F34: =S3!E33 -> 0 | G34: =S3!F33 -> 77.9 | H34: =S3!G33 -> 82.9 | I34: =S3!H33 -> 87.9 | J34: =S3!I33 -> 104.9 | K34: =S3!J33 -> 109.9 | ... S34: =S3!R33 -> 149.9
A35: S4 基本＋ワイズ＋エース | D35: =S4!C33 -> 0 | E35: =S4!D33 -> 0 | F35: =S4!E33 -> 11.15 | G35: =S4!F33 -> 213.9 | H35: =S4!G33 -> 218.9 | I35: =S4!H33 -> 223.9 | J35: =S4!I33 -> 240.9 | K35: =S4!J33 -> 245.9 | ... S35: =S4!R33 -> 285.9
A36: S5 全件（＋日本経営C＋セレサ） | D36: =S5!C33 -> 0 | E36: =S5!D33 -> 0 | F36: =S5!E33 -> 11.15 | G36: =S5!F33 -> 218.65 | H36: =S5!G33 -> 311.4 | I36: =S5!H33 -> 318.5 | J36: =S5!I33 -> 391 | K36: =S5!J33 -> 396 | ... S36: =S5!R33 -> 436
A38: Net Debt Capacity の月次推移（連結・調達前・各シートのモードに連動）
A39: シナリオ | D39: 2026/9 | E39: 2026/10 | F39: 2026/11 | G39: 2026/12 | H39: 2027/1 | I39: 2027/2 | J39: 2027/3 | K39: 2027/4 | L39: 2027/5 | M39: 2027/6 | N39: 2027/7 | O39: 2027/8 | P39: 2027/9 | Q39: 2027/10 | R39: 2027/11 | S39: 2027/12
A40: S1 基本（確定4件＋HT実行済） | D40: =S1!C42 -> 315.2 | E40: =S1!D42 -> 302.9 | F40: =S1!E42 -> 421.4 | G40: =S1!F42 -> 348.2 | H40: =S1!G42 -> 436.1 | I40: =S1!H42 -> 436 | J40: =S1!I42 -> 423.8 | K40: =S1!J42 -> 423.7 | ... S40: =S1!R42 -> 372.5
A41: S2 基本＋ワイズケア | D41: =S2!C42 -> 315.2 | E41: =S2!D42 -> 294.2 | F41: =S2!E42 -> 448.4 | G41: =S2!F42 -> 375.2 | H41: =S2!G42 -> 463.1 | I41: =S2!H42 -> 462.9 | J41: =S2!I42 -> 450.8 | K41: =S2!J42 -> 450.6 | ... S41: =S2!R42 -> 399.5
A42: S3 基本＋エーステイスト | D42: =S3!C42 -> 315.2 | E42: =S3!D42 -> 300.2 | F42: =S3!E42 -> 416.7 | G42: =S3!F42 -> 380.4 | H42: =S3!G42 -> 468.2 | I42: =S3!H42 -> 468 | J42: =S3!I42 -> 455.9 | K42: =S3!J42 -> 455.8 | ... S42: =S3!R42 -> 404.6
A43: S4 基本＋ワイズ＋エース | D43: =S4!C42 -> 315.2 | E43: =S4!D42 -> 291.5 | F43: =S4!E42 -> 443.7 | G43: =S4!F42 -> 407.3 | H43: =S4!G42 -> 495.2 | I43: =S4!H42 -> 495 | J43: =S4!I42 -> 482.9 | K43: =S4!J42 -> 482.7 | ... S43: =S4!R42 -> 431.5
A44: S5 全件（＋日本経営C＋セレサ） | D44: =S5!C42 -> 315.2 | E44: =S5!D42 -> 291.5 | F44: =S5!E42 -> 443.7 | G44: =S5!F42 -> 402.7 | H44: =S5!G42 -> 485.8 | I44: =S5!H42 -> 483.6 | J44: =S5!I42 -> 490.9 | K44: =S5!J42 -> 490.8 | ... S44: =S5!R42 -> 439.6
A87: 売上36億円への道筋 — 戦略別モンテカルロ結果（2万回・手出し最小化ベース・値貼付。詳細はHTML資料 第8章）
A88: 戦略 | B88: 追う案件数 | C88: 36億円到達確率（2027/12） | D88: 期待売上（年換算） | E88: 売上P50 | F88: 売上P80 | G88: 必要資金P50 | H88: 必要資金P80 | I88: 到達時の必要資金（中央値） | J88: 全件成約時の売上
A89: A 確定4件＋中型積み上げ（大型なし） | B89: 12 | C89: 0.38 | D89: 3460 | E89: 3449 | F89: 3908 | G89: 475 | H89: 587 | I89: 595 | J89: 4826
...

Sheet 前提
A1: 前提（入力シート）— 青字＝入力値、黒字＝数式。金額は百万円・税込
A3: 期首現預金（EEFUL HD単体・2026年8月末） | B3: 366.3
A4: 安全水準（HD手元現預金の下限） | B4: 100
A5: 年換算オーガニック売上（HT＋HD） | B5: 1230
A6: 年換算オーガニック調整後EBITDA | B6: 60
A7: 連結有利子負債（2026年8月末） | B7: 414.9
A8: モードの意味 | B8: 共通＝どちらのモードでも発生／現行＝LOI通りHDが全額負担／最小化＝退職金・対象会社資金・対象会社借入で手出しを圧縮した案
A10: 案件 | B10: 項目 | C10: モード | D10: 2026/9 | E10: 2026/10 | F10: 2026/11 | G10: 2026/12 | H10: 2027/1 | I10: 2027/2 | J10: 2027/3 | K10: 2027/4 | L10: 2027/5 | M10: 2027/6 | N10: 2027/7 | O10: 2027/8 | P10: 2027/9 | Q10: 2027/10 | R10: 2027/11 | S10: 2027/12 | T10: 合計
A11: HD運営費 | B11: 受取管理料控除後の運営費（9〜12月▲7、2027年▲5） | C11: 共通 | D11: -7 | E11: -7 | F11: -7 | G11: -7 | H11: -5 | I11: -5 | J11: -5 | K11: -5 | L11: -5 | M11: -5 | N11: -5 | O11: -5 | P11: -5 | Q11: -5 | R11: -5 | S11: -5 | T11: =SUM(D11:S11) -> -88
A12: HT100%化 | B12: 残株51%取得（9/11支払済） | C12: 共通 | D12: 30 | E12: 0 | F12: 0 | G12: 0 | H12: 0 | I12: 0 | J12: 0 | K12: 0 | L12: 0 | M12: 0 | N12: 0 | O12: 0 | P12: 0 | Q12: 0 | R12: 0 | S12: 0 | T12: =SUM(D12:S12) -> 30
A13: メディプロ | B13: DD費用（財務・法務） | C13: 共通 | D13: 0 | E13: 1.5 | F13: 0 | G13: 0 | H13: 0 | I13: 0 | J13: 0 | K13: 0 | L13: 0 | M13: 0 | N13: 0 | O13: 0 | P13: 0 | Q13: 0 | R13: 0 | S13: 0 | T13: =SUM(D13:S13) -> 1.5
A14: メディプロ | B14: 株式対価（70−公庫借入44.85残置） | C14: 共通 | D14: 0 | E14: 0 | F14: 25 | G14: 0 | H14: 0 | I14: 0 | J14: 0 | K14: 0 | L14: 0 | M14: 0 | N14: 0 | O14: 0 | P14: 0 | Q14: 0 | R14: 0 | S14: 0 | T14: =SUM(D14:S14) -> 25
A15: メディプロ | B15: 仲介手数料（バトンズ・契約書未確認 3.3〜8.8） | C15: 共通 | D15: 0 | E15: 0 | F15: 5.5 | G15: 0 | H15: 0 | I15: 0 | J15: 0 | K15: 0 | L15: 0 | M15: 0 | N15: 0 | O15: 0 | P15: 0 | Q15: 0 | R15: 0 | S15: 0 | T15: =SUM(D15:S15) -> 5.5
A16: ヒューマンアイ | B16: DD費用 | C16: 共通 | D16: 0 | E16: 1.5 | F16: 0 | G16: 0 | H16: 0 | I16: 0 | J16: 0 | K16: 0 | L16: 0 | M16: 0 | N16: 0 | O16: 0 | P16: 0 | Q16: 0 | R16: 0 | S16: 0 | T16: =SUM(D16:S16) -> 1.5
A17: ヒューマンアイ | B17: 仲介手数料（CBヘルスケア・最低報酬1,000万円・最終契約時） | C17: 共通 | D17: 0 | E17: 11 | F17: 0 | G17: 0 | H17: 0 | I17: 0 | J17: 0 | K17: 0 | L17: 0 | M17: 0 | N17: 0 | O17: 0 | P17: 0 | Q17: 0 | R17: 0 | S17: 0 | T17: =SUM(D17:S17) -> 11
A18: ヒューマンアイ | B18: 事業譲渡対価（22税別）一括 | C18: 現行 | D18: 0 | E18: 0 | F18: 0 | G18: 24 | H18: 0 | I18: 0 | J18: 0 | K18: 0 | L18: 0 | M18: 0 | N18: 0 | O18: 0 | P18: 0 | Q18: 0 | R18: 0 | S18: 0 | T18: =SUM(D18:S18) -> 24
A19: ヒューマンアイ | B19: 事業譲渡対価 半額を2027/3に繰延（要交渉） | C19: 最小化 | D19: 0 | E19: 0 | F19: 0 | G19: 12 | H19: 0 | I19: 0 | J19: 12 | K19: 0 | L19: 0 | M19: 0 | N19: 0 | O19: 0 | P19: 0 | Q19: 0 | R19: 0 | S19: 0 | T19: =SUM(D19:S19) -> 24
A20: クレッシェンド | B20: DD費用 | C20: 共通 | D20: 0 | E20: 2 | F20: 0 | G20: 0 | H20: 0 | I20: 0 | J20: 0 | K20: 0 | L20: 0 | M20: 0 | N20: 0 | O20: 0 | P20: 0 | Q20: 0 | R20: 0 | S20: 0 | T20: =SUM(D20:S20) -> 2
A21: クレッシェンド | B21: 仲介手数料（ストライク・基本合意時） | C21: 共通 | D21: 0 | E21: 1.1 | F21: 0 | G21: 0 | H21: 0 | I21: 0 | J21: 0 | K21: 0 | L21: 0 | M21: 0 | N21: 0 | O21: 0 | P21: 0 | Q21: 0 | R21: 0 | S21: 0 | T21: =SUM(D21:S21) -> 1.1
A22: クレッシェンド | B22: 株式対価10＋奥様退職金3（奥様分は対象会社資金） | C22: 共通 | D22: 0 | E22: 0 | F22: 10 | G22: 0 | H22: 0 | I22: 0 | J22: 0 | K22: 0 | L22: 0 | M22: 0 | N22: 0 | O22: 0 | P22: 0 | Q22: 0 | R22: 0 | S22: 0 | T22: =SUM(D22:S22) -> 10
... A51: シルバーメディカル | B51: 対価250のうちHD負担：退職金100＋役員貸付・未収金58の回収で相殺 | C51: 最小化 | D51: 0 | E51: 0 | F51: 0 | G51: 92 | H51: 0 | I51: 0 | J51: 0 | K51: 0 | L51: 0 | M51: 0 | N51: 0 | O51: 0 | P51: 0 | Q51: 0 | R51: 0 | S51: 0 | T51: =SUM(D51:S51) -> 92
A55: Net Debt Capacity の前提（連結）
A56: オーガニック 調整後EBITDA年換算 | C56: 共通 | D56: 32 | E56: 34 | F56: 37 | G56: 39 | H56: 60 | I56: 60 | J56: 60 | K56: 60 | L56: 60 | M56: 60 | N56: 60 | O56: 60 | P56: 60 | Q56: 60 | R56: 60 | S56: 60
A57: HT 現預金（12月賞与30を反映） | C57: 共通 | D57: 76 | E57: 76 | F57: 76 | G57: 46 | H57: 50 | I57: 50 | J57: 50 | K57: 50 | L57: 50 | M57: 50 | N57: 50 | O57: 50 | P57: 50 | Q57: 50 | R57: 50 | S57: 50
A58: 既存有利子負債（8月末414.9から月4.85返済） | C58: 共通 | D58: =前提!$B$7-1*$B$59 -> 410.05 | E58: =前提!$B$7-2*$B$59 -> 405.2 | F58: =前提!$B$7-3*$B$59 -> 400.35 | G58: =前提!$B$7-4*$B$59 -> 395.5 | H58: =前提!$B$7-5*$B$59 -> 390.65 | I58: =前提!$B$7-6*$B$59 -> 385.8 | J58: =前提!$B$7-7*$B$59 -> 380.95 | K58: =前提!$B$7-8*$B$59 -> 376.1 | L58: =前提!$B$7-9*$B$59 -> 371.25 | M58: =前提!$B$7-10*$B$59 -> 366.4 | N58: =前提!$B$7-11*$B$59 -> 361.55 | O58: =前提!$B$7-12*$B$59 -> 356.7 | P58: =前提!$B$7-13*$B$59 -> 351.85 | Q58: =前提!$B$7-14*$B$59 -> 347 | R58: =前提!$B$7-15*$B$59 -> 342.15 | S58: =前提!$B$7-16*$B$59 -> 337.3
A59: HT 月次元本返済 | B59: 4.85
A60: 連結売掛金（HD17.7＋HT174） | B60: 192
A62: 出所：各案件LOI（シルバーメディカル9/5・ワイズケア9/11・エーステイスト9/15・クレッシェンド9/15）、DD管理表9/18、M&A総研 締結済アドバイザリー業務契約書（7/13）、SMS見積書（8/5）、CBヘルスケア案件概要書（7/14）、ストライク面談記録（7/24）、株主定例議事録8/24週、Slack #eeful-dbc（退職金スキーム検討）。運転資金の貸付は行わない前提。マイナスは対象会社レベル借入等によるHD負担の軽減。

Sheet 案件一覧
A1: 案件一覧（年換算・百万円）— 青字＝入力値、緑字＝他シート参照
A3: 案件 | B3: ステージ（9/22時点） | C3: スキーム | D3: 年間売上 | E3: 調整後EBITDA（現状） | F3: 同（改善後） | G3: 承継・残置負債 | H3: HD手出し（現行） | I3: HD手出し（最小化） | J3: 実行時期 | K3: 仲介／手数料（税込） | L3: 退職金スキーム・手出し圧縮の考え方 | M3: NDC：クロージング月（列番号 1=2026/9） | N3: NDC：連結売掛金 | O3: NDC：残置現金 | P3: NDC：対象会社借入（最小化） | Q3: NDC：借入月（列番号）
A4: HT100%化 | B4: 実行済 | C4: 残株51%取得 | D4: 0 | E4: 0 | F4: 0 | G4: 0 | H4: =SUMIFS(前提!$T$12:$T$51,前提!$A$12:$A$51,A4,前提!$C$12:$C$51,"共通")+SUMIFS(前提!$T$12:$T$51,前提!$A$12:$A$51,A4,前提!$C$12:$C$51,"現行") -> 30 | I4: =SUMIFS(前提!$T$12:$T$51,前提!$A$12:$A$51,A4,前提!$C$12:$C$51,"共通")+SUMIFS(前提!$T$12:$T$51,前提!$A$12:$A$51,A4,前提!$C$12:$C$51,"最小化") -> 30 | J4: 2026/9/11 | K4: — | L4: — | M4: 99 | N4: 0 | O4: 0 | P4: 0 | Q4: 99
A5: メディプロ | B5: DD（決済11/6） | C5: 会社分割＋株式譲渡 | D5: 97 | E5: 18 | F5: 29 | G5: 44.85 | H5: =SUMIFS(前提!$T$12:$T$51,前提!$A$12:$A$51,A5,前提!$C$12:$C$51,"共通")+SUMIFS(前提!$T$12:$T$51,前提!$A$12:$A$51,A5,前提!$C$12:$C$51,"現行") -> 32 | I5: =SUMIFS(前提!$T$12:$T$51,前提!$A$12:$A$51,A5,前提!$C$12:$C$51,"共通")+SUMIFS(前提!$T$12:$T$51,前提!$A$12:$A$51,A5,前提!$C$12:$C$51,"最小化") -> 32 | J5: 2026/11/6 | K5: バトンズ 5.5（契約書要確認） | L5: 公庫借入44.85を残置し株式対価を70→25に圧縮済み。分割後現金17.8は薄く追加圧縮余地は小 | M5: 3 | N5: 16 | O5: 18 | P5: 0 | Q5: 99
A6: ヒューマンアイ | B6: DD（基本合意期限9/30） | C6: 事業譲渡（デイ5拠点） | D6: 182 | E6: 6 | F6: 15 | G6: 0 | H6: =SUMIFS(前提!$T$12:$T$51,前提!$A$12:$A$51,A6,前提!$C$12:$C$51,"共通")+SUMIFS(前提!$T$12:$T$51,前提!$A$12:$A$51,A6,前提!$C$12:$C$51,"現行") -> 36.5 | I6: =SUMIFS(前提!$T$12:$T$51,前提!$A$12:$A$51,A6,前提!$C$12:$C$51,"共通")+SUMIFS(前提!$T$12:$T$51,前提!$A$12:$A$51,A6,前提!$C$12:$C$51,"最小化") -> 36.5 | J6: 2026/12/1 | K6: CBヘルスケア 11.0 | L6: 事業譲渡のため退職金スキーム不可。対価の半額繰延（2027/3）を売主グロップに交渉する余地 | M6: 4 | N6: 30 | O6: 0 | P6: 0 | Q6: 99
A7: クレッシェンド | B7: LOI受領内諾（9/22） | C7: 株式譲渡＋役員退職慰労金 | D7: 149 | E7: 20 | F7: 20 | G7: 0 | H7: =SUMIFS(前提!$T$12:$T$51,前提!$A$12:$A$51,A7,前提!$C$12:$C$51,"共通")+SUMIFS(前提!$T$12:$T$51,前提!$A$12:$A$51,A7,前提!$C$12:$C$51,"現行") -> 91.1 | I7: =SUMIFS(前提!$T$12:$T$51,前提!$A$12:$A$51,A7,前提!$C$12:$C$51,"共通")+SUMIFS(前提!$T$12:$T$51,前提!$A$12:$A$51,A7,前提!$C$12:$C$51,"最小化") -> 35.1 | J7: 2026/11中旬 | K7: ストライク 1.1＋22.0 | L7: 株式10＋退職金73（退任時）＋奥様3＋役員借入返済。退職金は損金算入で税効果22。原資は対象会社現金46＋対象会社の銀行借入（HD保証）に置換すればHD貸付50は不要 | M7: 3 | N7: 25 | O7: 10 | P7: 50 | Q7: 9
A8: ワイズケア | B8: LOI提出（9/11）・DD9月下旬〜 | C8: 2社株式譲渡（退職慰労金活用可） | D8: 485 | E8: 38 | F8: 66 | G8: 0 | H8: =SUMIFS(前提!$T$12:$T$51,前提!$A$12:$A$51,A8,前提!$C$12:$C$51,"共通")+SUMIFS(前提!$T$12:$T$51,前提!$A$12:$A$51,A8,前提!$C$12:$C$51,"現行") -> 266 | I8: =SUMIFS(前提!$T$12:$T$51,前提!$A$12:$A$51,A8,前提!$C$12:$C$51,"共通")+SUMIFS(前提!$T$12:$T$51,前提!$A$12:$A$51,A8,前提!$C$12:$C$51,"最小化") -> 136 | J8: 2026/11下旬 | K8: M&A総研 4.7＋42.3 | L8: LOIは『退職慰労金活用時も合計215』。net cash50を退職慰労金に充て株式対価165へ。さらに対象会社（EBITDA38〜66）で買収ローン80を組めばHD手出しは136 | M8: 3 | N8: 81 | O8: 10 | P8: 80 | Q8: 3
A9: エーステイスト | B9: LOI提出（9/15）・競合3社 | C9: 事業譲渡＋借入60.4引受 | D9: 676 | E9: 18 | F9: 43 | G9: 60.4 | H9: =SUMIFS(前提!$T$12:$T$51,前提!$A$12:$A$51,A9,前提!$C$12:$C$51,"共通")+SUMIFS(前提!$T$12:$T$51,前提!$A$12:$A$51,A9,前提!$C$12:$C$51,"現行") -> 74.5 | I9: =SUMIFS(前提!$T$12:$T$51,前提!$A$12:$A$51,A9,前提!$C$12:$C$51,"共通")+SUMIFS(前提!$T$12:$T$51,前提!$A$12:$A$51,A9,前提!$C$12:$C$51,"最小化") -> 74.5 | J9: 2026/12末 | K9: MACP 2.75＋24.75 | L9: 事業譲渡のため退職金スキーム不可。借入60.4の免責的引受で対価を45に圧縮済み。手数料27.5が対価の6割 | M9: 4 | N9: 85 | O9: 10 | P9: 0 | Q9: 99
A10: 日本経営センター | B10: LOI作成中（9/17 方針：奥様・息子退任・対価80） | C10: 株式100%譲渡＋退職金 | D10: 378 | E10: 12 | F10: 32 | G10: 32.9 | H10: =SUMIFS(前提!$T$12:$T$51,前提!$A$12:$A$51,A10,前提!$C$12:$C$51,"共通")+SUMIFS(前提!$T$12:$T$51,前提!$A$12:$A$51,A10,前提!$C$12:$C$51,"現行") -> 109.5 | I10: =SUMIFS(前提!$T$12:$T$51,前提!$A$12:$A$51,A10,前提!$C$12:$C$51,"共通")+SUMIFS(前提!$T$12:$T$51,前提!$A$12:$A$51,A10,前提!$C$12:$C$51,"最小化") -> 92.5 | J10: 2027/1 | K10: MACP 2.75＋24.75 | L10: 退任後EBITDA32に対し対価80＋手数料25で3.1倍。役員借入21.6の返済と退職金を対象会社現金・進行期キャッシュで賄い株式対価を63へ（Slack 9/17『手出しは退職金など使って9,000万ほど』） | M10: 5 | N10: 63 | O10: 5 | P10: 0 | Q10: 99
A11: セレサ | B11: 本格検討（9/18 対価試算） | C11: 株式譲渡（譲渡前配当＋株式） | D11: 140 | E11: 8 | F11: 8 | G11: 0 | H11: =SUMIFS(前提!$T$12:$T$51,前提!$A$12:$A$51,A11,前提!$C$12:$C$51,"共通")+SUMIFS(前提!$T$12:$T$51,前提!$A$12:$A$51,A11,前提!$C$12:$C$51,"現行") -> 62.2 | I11: =SUMIFS(前提!$T$12:$T$51,前提!$A$12:$A$51,A11,前提!$C$12:$C$51,"共通")+SUMIFS(前提!$T$12:$T$51,前提!$A$12:$A$51,A11,前提!$C$12:$C$51,"最小化") -> 57.6 | J11: 2027/3 | K11: SMS 0.6＋11.5（配当除外なら6.9） | L11: 対価130のうち81.4を譲渡前配当（対象会社現金）で充当済み。手数料の算定基礎から配当を外す再見積を交渉（見積有効期限9/4切れ） | M11: 7 | N11: 23 | O11: 20 | P11: 0 | Q11: 99
A12: シルバーメディカル | B12: DD（LOI 9/5・口頭合意9/12） | C12: 株式譲渡＋役員退職慰労金 | D12: 777 | E12: -21 | F12: 16 | G12: 83 | H12: =SUMIFS(前提!$T$12:$T$51,前提!$A$12:$A$51,A12,前提!$C$12:$C$51,"共通")+SUMIFS(前提!$T$12:$T$51,前提!$A$12:$A$51,A12,前提!$C$12:$C$51,"現行") -> 178.1 | I12: =SUMIFS(前提!$T$12:$T$51,前提!$A$12:$A$51,A12,前提!$C$12:$C$51,"共通")+SUMIFS(前提!$T$12:$T$51,前提!$A$12:$A$51,A12,前提!$C$12:$C$51,"最小化") -> 120.1 | J12: 2026/12（SPA11月末） | K12: ストライク 1.1＋22.0 | L12: LOIは『2.5億＝株式対価＋役員退職慰労金』。現預金134のうち約100を退職慰労金に充て、吉澤氏向け貸付・未収金58の返済で相殺すればHD手出しは約92（DBC馬氏『手出し少なくいける』）。分社型吸収分割でのれん償却も選択肢だが許認可の巻き直しが必要 | M12: 4 | N12: 130 | O12: 60 | P12: 0 | Q12: 99
A14: 退職金スキームの共通ルール
A15: 1. 役員退職慰労金は対象会社の損金（功績倍率法：最終報酬月額×在任年数×功績倍率≈3.0が目安。超過分は否認リスク）。売主は退職所得課税（1/2課税・勤続控除）で株式譲渡（20.315%）より手取りが増えるケースが多い
A16: 2. 原資は対象会社の現預金・進行期キャッシュ。不足分は対象会社の銀行借入（HD保証）で賄えばHDの手出しは増えない。HDからの貸付は運転資金貸付を行わない方針に照らし最小化
A17: 3. 退職金支給には退任が必要。引継ぎ期間中は代表取締役に留任し指揮命令権を外す設計（ストライク小玉氏へ説明済み）。損金算入限度は退任時の役職で変わる
A18: 4. 退職慰労金を対価に含める場合、M&A総研・SMS等の移動総資産型レーマンでは手数料の算定基礎に加算されるため、手数料は下がらない（ワイズケア・セレサ）
A19: 5. 事業譲渡（ヒューマンアイ・エーステイスト）は退職金スキームが使えない代わりに、のれん償却（5年）による買主側の節税と負債非承継の利点がある

Sheet 手出し内訳
A1: 手出しの内訳 — EEFUL HDの現金が必要なもの（HD現金）と、対象会社資金・借入・売主側で賄うもの（百万円・税込）
A2: 青字＝入力値。『HD現金』の行がEEFUL HDの手出し。『対象会社借入』のうち株式対価に充当する行はHD手出しの控除。前提シートの支出明細と整合（下の検算欄で確認）
A4: 案件 | B4: 項目 | C4: 支払主体 | D4: 現行 | E4: 手出し最小化 | F4: 時期・備考
A5: HT100%化 | B5: 残株51%の株式対価 | C5: HD現金 | D5: 30 | E5: 30 | F5: 2026/9（支払済）
A6: メディプロ | B6: 株式対価（70−公庫借入残置44.85） | C6: HD現金 | D6: 25 | E6: 25 | F6: 2026/11
A7: メディプロ | B7: 日本政策金融公庫借入の残置 | C7: 負債承継・残置 | D7: 44.85 | E7: 44.85 | F7: 対象会社に残る
A8: メディプロ | B8: 役員借入金の返済（クロージング後） | C8: 対象会社資金 | F8: 金額精査中
A9: メディプロ | B9: 仲介手数料（バトンズ） | C9: HD現金 | D9: 5.5 | E9: 5.5 | F9: 2026/11
A10: メディプロ | B10: DD費用（財務・法務） | C10: HD現金 | D10: 1.5 | E10: 1.5 | F10: 2026/10
A11: ヒューマンアイ | B11: 事業譲渡対価（22税別） | C11: HD現金 | D11: 24 | E11: 24 | F11: 現行：2026/12一括／最小化：12を2026/12・12を2027/3（要交渉）
A12: ヒューマンアイ | B12: 仲介手数料（CBヘルスケア・最低報酬） | C12: HD現金 | D12: 11 | E12: 11 | F12: 2026/10（最終契約時）
A13: ヒューマンアイ | B13: DD費用 | C13: HD現金 | D13: 1.5 | E13: 1.5 | F13: 2026/10
A14: クレッシェンド | B14: 株式対価 | C14: HD現金 | D14: 10 | E14: 10 | F14: 2026/11
A15: クレッシェンド | B15: 役員退職金（小津野了氏・退任時）のうち対象会社現金分 | C15: 対象会社資金 | D15: 23 | E15: 23 | F15: 2027/5（引継ぎ6ヶ月後）
A16: クレッシェンド | B16: 役員退職金の残り原資 | C16: HD現金 | D16: 50 | E16: 0 | F16: 現行：EEFUL貸付 2027/5
A17: クレッシェンド | B17: 役員退職金の残り原資（対象会社の銀行借入・HD保証） | C17: 対象会社借入 | D17: 0 | E17: 50 | F17: 最小化：2027/5
A18: クレッシェンド | B18: 奥様退職金3・役員借入返済・リース車両清算 | C18: 対象会社資金 | F18: 2026/11 クロージング時（進行期キャッシュ含む）
A19: クレッシェンド | B19: 引継ぎ報酬 1×6ヶ月 | C19: HD現金 | D19: 6 | E19: 0 | F19: 現行：HD負担 2026/12〜2027/5
A20: クレッシェンド | B20: 引継ぎ報酬 1×6ヶ月（対象会社の役員報酬として） | C20: 対象会社資金 | D20: 0 | E20: 6 | F20: 最小化
A21: クレッシェンド | B21: 仲介手数料（ストライク） | C21: HD現金 | D21: 23.1 | E21: 23.1 | F21: 1.1：2026/10 ／ 22.0：2026/11
A22: クレッシェンド | B22: DD費用 | C22: HD現金 | D22: 2 | E22: 2 | F22: 2026/10
A23: ワイズケア | B23: 株式対価 | C23: HD現金 | D23: 215 | E23: 165 | F23: 2026/11下旬
A24: ワイズケア | B24: 役員退職慰労金（対価215の内数） | C24: 対象会社資金 | D24: 0 | E24: 50 | F24: 最小化：対象会社現金（net cash50）
A25: ワイズケア | B25: 買収ローン（対象会社・HD保証）による株式対価の充当 | C25: 対象会社借入 | D25: 0 | E25: 80 | F25: 最小化：2026/11（HD手出しを▲80）
A26: ワイズケア | B26: 仲介手数料（M&A総研） | C26: HD現金 | D26: 47 | E26: 47 | F26: 4.7：2026/10 ／ 42.3：2026/11
A27: ワイズケア | B27: DD費用（2社） | C27: HD現金 | D27: 4 | E27: 4 | F27: 2026/10
A28: エーステイスト | B28: 事業譲渡対価（税込） | C28: HD現金 | D28: 45 | E28: 45 | F28: 2026/12末
A29: エーステイスト | B29: 金融機関借入の免責的債務引受 | C29: 負債承継・残置 | D29: 60.4 | E29: 60.4 | F29: 承継法人が引受（現金不要）
A30: エーステイスト | B30: 役員借入金127.6の放棄（売主） | C30: 売主側 | D30: 67.6 | E30: 67.6 | F30: LOIシナリオ表9/8：返済60・放棄67.6
... A34: 日本経営センター | B34: 役員借入21.6のうち対象会社現金で返済 | C34: 対象会社資金 | D34: 0 | E34: 17 | F34: 最小化：2027/1
A35: 日本経営センター | B35: 役員退職金（奥様・息子退任・対価の内数） | C35: 対象会社資金 | F35: 損金限度を要確認
A36: 日本経営センター | B36: 仲介手数料（MACP・最低報酬） | C36: HD現金 | D36: 27.5 | E36: 27.5 | F36: 2.75：2026/12 ／ 24.75：2027/1
A37: 日本経営センター | B37: DD費用 | C37: HD現金 | D37: 2 | E37: 2 | F37: 2026/12
A38: セレサ | B38: 株式対価（130−配当81.4） | C38: HD現金 | D38: 48.6 | E38: 48.6 | F38: 2027/3
A39: セレサ | B39: 譲渡前配当 | C39: 対象会社資金 | D39: 81.4 | E39: 81.4 | F39: 2027/3 クロージング前
A40: セレサ | B40: 仲介手数料（SMS） | C40: HD現金 | D40: 12.1 | E40: 7.5 | F40: 0.6：2027/1 ／ 残：2027/3（最小化は配当除外で再見積）
A41: セレサ | B41: DD費用 | C41: HD現金 | D41: 1.5 | E41: 1.5 | F41: 2027/2
A42: シルバーメディカル | B42: 株式対価（250−退職慰労金−貸付回収） | C42: HD現金 | D42: 150 | E42: 92 | F42: 2026/12
A43: シルバーメディカル | B43: 役員退職慰労金（対価250の内数） | C43: 対象会社資金 | D43: 100 | E43: 100 | F43: 2026/12 対象会社現金134から
A44: シルバーメディカル | B44: 吉澤氏向け役員貸付・未収入金の返済（対価から控除） | C44: 売主側 | D44: 0 | E44: 58 | F44: 最小化：譲渡実行時に返済
...

Sheet S1
A1: S1 基本（確定4件＋HT実行済） — HD単体 月次キャッシュ推移（百万円）
A2: 実行フラグ（1＝実行、0＝見送り）とモード（現行／最小化）を変えると全体が再計算されます。青字＝入力値
A3: モード | B3: 最小化 | C3: ← 「現行」または「最小化」
A5: 案件 | B5: 実行フラグ
A6: HT100%化 | B6: 1
A7: メディプロ | B7: 1
A8: ヒューマンアイ | B8: 1
A9: クレッシェンド | B9: 1
A10: ワイズケア | B10: 0
A11: エーステイスト | B11: 0
A12: 日本経営センター | B12: 0
A13: セレサ | B13: 0
A14: シルバーメディカル | B14: 1
A17: 項目 | C17: 2026/9 | D17: 2026/10 | E17: 2026/11 | F17: 2026/12 | G17: 2027/1 | H17: 2027/2 | I17: 2027/3 | J17: 2027/4 | K17: 2027/5 | L17: 2027/6 | M17: 2027/7 | N17: 2027/8 | O17: 2027/9 | P17: 2027/10 | Q17: 2027/11 | R17: 2027/12 | S17: 合計
A18: 期首現預金 | C18: =前提!$B$3 -> 366.3 | D18: =C31 -> 329.3 | E18: =D31 -> 304.1 | F18: =E31 -> 229.6 | G18: =F31 -> 96.6 | H18: =G31 -> 91.6 | I18: =H31 -> 86.6 | J18: =I31 -> 69.6 | K18: =J31 -> 64.6 | ... R18: =Q31 -> 29.6
A19: HD運営費 | C19: =前提!D$11 -> -7 | D19: =前提!E$11 -> -7 | E19: =前提!F$11 -> -7 | F19: =前提!G$11 -> -7 | G19: =前提!H$11 -> -5 | H19: =前提!I$11 -> -5 | I19: =前提!J$11 -> -5 | J19: =前提!K$11 -> -5 | ... R19: =前提!S$11 -> -5 | S19: =SUM(C19:R19) -> -88
A20: 案件支出（マイナスは対象会社借入等による軽減）
A21: HT100%化 | C21: =-$B$6*(SUMIFS(前提!$D$12:$D$51,前提!$A$12:$A$51,TRIM($A21),前提!$C$12:$C$51,"共通")+SUMIFS(前提!$D$12:$D$51,前提!$A$12:$A$51,TRIM($A21),前提!$C$12:$C$51,$B$3)) -> -30 | D21: =-$B$6*(SUMIFS(前提!$E$12:$E$51,前提!$A$12:$A$51,TRIM($A21),前提!$C$12:$C$51,"共通")+SUMIFS(前提!$E$12:$E$51,前提!$A$12:$A$51,TRIM($A21),前提!$C$12:$C$51,$B$3)) -> 0 | E21: =-$B$6*(SUMIFS(前提!$F$12:$F$51,前提!$A$12:$A$51,TRIM($A21),前提!$C$12:$C$51,"共通")+SUMIFS(前提!$F$12:$F$51,前提!$A$12:$A$51,TRIM($A21),前提!$C$12:$C$51,$B$3)) -> 0 | F21: =-$B$6*(SUMIFS(前提!$G$12:$G$51,前提!$A$12:$A$51,TRIM($A21),前提!$C$12:$C$51,"共通")+SUMIFS(前提!$G$12:$G$51,前提!$A$12:$A$51,TRIM($A21),前提!$C$12:$C$51,$B$3)) -> 0 | G21: =-$B$6*(SUMIFS(前提!$H$12:$H$51,前提!$A$12:$A$51,TRIM($A21),前提!$C$12:$C$51,"共通")+SUMIFS(前提!$H$12:$H$51,前提!$A$12:$A$51,TRIM($A21),前提!$C$12:$C$51,$B$3)) -> 0 | H21: =-$B$6*(SUMIFS(前提!$I$12:$I$51,前提!$A$12:$A$51,TRIM($A21),前提!$C$12:$C$51,"共通")+SUMIFS(前提!$I$12:$I$51,前提!$A$12:$A$51,TRIM($A21),前提!$C$12:$C$51,$B$3)) -> 0 | I21: =-$B$6*(SUMIFS(前提!$J$12:$J$51,前提!$A$12:$A$51,TRIM($A21),前提!$C$12:$C$51,"共通")+SUMIFS(前提!$J$12:$J$51,前提!$A$12:$A$51,TRIM($A21),前提!$C$12:$C$51,$B$3)) -> 0 | J21: =-$B$6*(SUMIFS(前提!$K$12:$K$51,前提!$A$12:$A$51,TRIM($A21),前提!$C$12:$C$51,"共通")+SUMIFS(前提!$K$12:$K$51,前提!$A$12:$A$51,TRIM($A21),前提!$C$12:$C$51,$B$3)) -> 0 | K21: =-$B$6*(SUMIFS(前提!$L$12:$L$51,前提!$A$12:$A$51,TRIM($A21),前提!$C$12:$C$51,"共通")+SUMIFS(前提!$L$12:$L$51,前提!$A$12:$A$51,TRIM($A21),前提!$C$12:$C$51,$B$3)) -> 0 | L21: =-$B$6*(SUMIFS(前提!$M$12:$M$51,前提!$A$12:$A$51,TRIM($A21),前提!$C$12:$C$51,"共通")+SUMIFS(前提!$M$12:$M$51,前提!$A$12:$A$51,TRIM($A21),前提!$C$12:$C$51,$B$3)) -> 0 | M21: =-$B$6*(SUMIFS(前提!$N$12:$N$51,前提!$A$12:$A$51,TRIM($A21),前提!$C$12:$C$51,"共通")+SUMIFS(前提!$N$12:$N$51,前提!$A$12:$A$51,TRIM($A21),前提!$C$12:$C$51,$B$3)) -> 0 | N21: =-$B$6*(SUMIFS(前提!$O$12:$O$51,前提!$A$12:$A$51,TRIM($A21),前提!$C$12:$C$51,"共通")+SUMIFS(前提!$O$12:$O$51,前提!$A$12:$A$51,TRIM($A21),前提!$C$12:$C$51,$B$3)) -> 0 | O21: =-$B$6*(SUMIFS(前提!$P$12:$P$51,前提!$A$12:$A$51,TRIM($A21),前提!$C$12:$C$51,"共通")+SUMIFS(前提!$P$12:$P$51,前提!$A$12:$A$51,TRIM($A21),前提!$C$12:$C$51,$B$3)) -> 0 | P21: =-$B$6*(SUMIFS(前提!$Q$12:$Q$51,前提!$A$12:$A$51,TRIM($A21),前提!$C$12:$C$51,"共通")+SUMIFS(前提!$Q$12:$Q$51,前提!$A$12:$A$51,TRIM($A21),前提!$C$12:$C$51,$B$3)) -> 0 | Q21: =-$B$6*(SUMIFS(前提!$R$12:$R$51,前提!$A$12:$A$51,TRIM($A21),前提!$C$12:$C$51,"共通")+SUMIFS(前提!$R$12:$R$51,前提!$A$12:$A$51,TRIM($A21),前提!$C$12:$C$51,$B$3)) -> 0 | R21: =-$B$6*(SUMIFS(前提!$S$12:$S$51,前提!$A$12:$A$51,TRIM($A21),前提!$C$12:$C$51,"共通")+SUMIFS(前提!$S$12:$S$51,前提!$A$12:$A$51,TRIM($A21),前提!$C$12:$C$51,$B$3)) -> 0 | S21: =SUM(C21:R21) -> -30
A22: メディプロ | C22: =-$B$7*(SUMIFS(前提!$D$12:$D$51,前提!$A$12:$A$51,TRIM($A22),前提!$C$12:$C$51,"共通")+SUMIFS(前提!$D$12:$D$51,前提!$A$12:$A$51,TRIM($A22),前提!$C$12:$C$51,$B$3)) -> 0 | D22: =-$B$7*(SUMIFS(前提!$E$12:$E$51,前提!$A$12:$A$51,TRIM($A22),前提!$C$12:$C$51,"共通")+SUMIFS(前提!$E$12:$E$51,前提!$A$12:$A$51,TRIM($A22),前提!$C$12:$C$51,$B$3)) -> -1.5 | E22: =-$B$7*(SUMIFS(前提!$F$12:$F$51,前提!$A$12:$A$51,TRIM($A22),前提!$C$12:$C$51,"共通")+SUMIFS(前提!$F$12:$F$51,前提!$A$12:$A$51,TRIM($A22),前提!$C$12:$C$51,$B$3)) -> -30.5 | F22: =-$B$7*(SUMIFS(前提!$G$12:$G$51,前提!$A$12:$A$51,TRIM($A22),前提!$C$12:$C$51,"共通")+SUMIFS(前提!$G$12:$G$51,前提!$A$12:$A$51,TRIM($A22),前提!$C$12:$C$51,$B$3)) -> 0 | G22: =-$B$7*(SUMIFS(前提!$H$12:$H$51,前提!$A$12:$A$51,TRIM($A22),前提!$C$12:$C$51,"共通")+SUMIFS(前提!$H$12:$H$51,前提!$A$12:$A$51,TRIM($A22),前提!$C$12:$C$51,$B$3)) -> 0 | H22: =-$B$7*(SUMIFS(前提!$I$12:$I$51,前提!$A$12:$A$51,TRIM($A22),前提!$C$12:$C$51,"共通")+SUMIFS(前提!$I$12:$I$51,前提!$A$12:$A$51,TRIM($A22),前提!$C$12:$C$51,$B$3)) -> 0 | I22: =-$B$7*(SUMIFS(前提!$J$12:$J$51,前提!$A$12:$A$51,TRIM($A22),前提!$C$12:$C$51,"共通")+SUMIFS(前提!$J$12:$J$51,前提!$A$12:$A$51,TRIM($A22),前提!$C$12:$C$51,$B$3)) -> 0 | J22: =-$B$7*(SUMIFS(前提!$K$12:$K$51,前提!$A$12:$A$51,TRIM($A22),前提!$C$12:$C$51,"共通")+SUMIFS(前提!$K$12:$K$51,前提!$A$12:$A$51,TRIM($A22),前提!$C$12:$C$51,$B$3)) -> 0 | K22: =-$B$7*(SUMIFS(前提!$L$12:$L$51,前提!$A$12:$A$51,TRIM($A22),前提!$C$12:$C$51,"共通")+SUMIFS(前提!$L$12:$L$51,前提!$A$12:$A$51,TRIM($A22),前提!$C$12:$C$51,$B$3)) -> 0 | L22: =-$B$7*(SUMIFS(前提!$M$12:$M$51,前提!$A$12:$A$51,TRIM($A22),前提!$C$12:$C$51,"共通")+SUMIFS(前提!$M$12:$M$51,前提!$A$12:$A$51,TRIM($A22),前提!$C$12:$C$51,$B$3)) -> 0 | M22: =-$B$7*(SUMIFS(前提!$N$12:$N$51,前提!$A$12:$A$51,TRIM($A22),前提!$C$12:$C$51,"共通")+SUMIFS(前提!$N$12:$N$51,前提!$A$12:$A$51,TRIM($A22),前提!$C$12:$C$51,$B$3)) -> 0 | N22: =-$B$7*(SUMIFS(前提!$O$12:$O$51,前提!$A$12:$A$51,TRIM($A22),前提!$C$12:$C$51,"共通")+SUMIFS(前提!$O$12:$O$51,前提!$A$12:$A$51,TRIM($A22),前提!$C$12:$C$51,$B$3)) -> 0 | O22: =-$B$7*(SUMIFS(前提!$P$12:$P$51,前提!$A$12:$A$51,TRIM($A22),前提!$C$12:$C$51,"共通")+SUMIFS(前提!$P$12:$P$51,前提!$A$12:$A$51,TRIM($A22),前提!$C$12:$C$51,$B$3)) -> 0 | P22: =-$B$7*(SUMIFS(前提!$Q$12:$Q$51,前提!$A$12:$A$51,TRIM($A22),前提!$C$12:$C$51,"共通")+SUMIFS(前提!$Q$12:$Q$51,前提!$A$12:$A$51,TRIM($A22),前提!$C$12:$C$51,$B$3)) -> 0 | Q22: =-$B$7*(SUMIFS(前提!$R$12:$R$51,前提!$A$12:$A$51,TRIM($A22),前提!$C$12:$C$51,"共通")+SUMIFS(前提!$R$12:$R$51,前提!$A$12:$A$51,TRIM($A22),前提!$C$12:$C$51,$B$3)) -> 0 | R22: =-$B$7*(SUMIFS(前提!$S$12:$S$51,前提!$A$12:$A$51,TRIM($A22),前提!$C$12:$C$51,"共通")+SUMIFS(前提!$S$12:$S$51,前提!$A$12:$A$51,TRIM($A22),前提!$C$12:$C$51,$B$3)) -> 0 | S22: =SUM(C22:R22) -> -32
A23: ヒューマンアイ | C23: =-$B$8*(SUMIFS(前提!$D$12:$D$51,前提!$A$12:$A$51,TRIM($A23),前提!$C$12:$C$51,"共通")+SUMIFS(前提!$D$12:$D$51,前提!$A$12:$A$51,TRIM($A23),前提!$C$12:$C$51,$B$3)) -> 0 | D23: =-$B$8*(SUMIFS(前提!$E$12:$E$51,前提!$A$12:$A$51,TRIM($A23),前提!$C$12:$C$51,"共通")+SUMIFS(前提!$E$12:$E$51,前提!$A$12:$A$51,TRIM($A23),前提!$C$12:$C$51,$B$3)) -> -12.5 | E23: =-$B$8*(SUMIFS(前提!$F$12:$F$51,前提!$A$12:$A$51,TRIM($A23),前提!$C$12:$C$51,"共通")+SUMIFS(前提!$F$12:$F$51,前提!$A$12:$A$51,TRIM($A23),前提!$C$12:$C$51,$B$3)) -> 0 | F23: =-$B$8*(SUMIFS(前提!$G$12:$G$51,前提!$A$12:$A$51,TRIM($A23),前提!$C$12:$C$51,"共通")+SUMIFS(前提!$G$12:$G$51,前提!$A$12:$A$51,TRIM($A23),前提!$C$12:$C$51,$B$3)) -> -12 | G23: =-$B$8*(SUMIFS(前提!$H$12:$H$51,前提!$A$12:$A$51,TRIM($A23),前提!$C$12:$C$51,"共通")+SUMIFS(前提!$H$12:$H$51,前提!$A$12:$A$51,TRIM($A23),前提!$C$12:$C$51,$B$3)) -> 0 | H23: =-$B$8*(SUMIFS(前提!$I$12:$I$51,前提!$A$12:$A$51,TRIM($A23),前提!$C$12:$C$51,"共通")+SUMIFS(前提!$I$12:$I$51,前提!$A$12:$A$51,TRIM($A23),前提!$C$12:$C$51,$B$3)) -> 0 | I23: =-$B$8*(SUMIFS(前提!$J$12:$J$51,前提!$A$12:$A$51,TRIM($A23),前提!$C$12:$C$51,"共通")+SUMIFS(前提!$J$12:$J$51,前提!$A$12:$A$51,TRIM($A23),前提!$C$12:$C$51,$B$3)) -> -12 | J23: =-$B$8*(SUMIFS(前提!$K$12:$K$51,前提!$A$12:$A$51,TRIM($A23),前提!$C$12:$C$51,"共通")+SUMIFS(前提!$K$12:$K$51,前提!$A$12:$A$51,TRIM($A23),前提!$C$12:$C$51,$B$3)) -> 0 | K23: =-$B$8*(SUMIFS(前提!$L$12:$L$51,前提!$A$12:$A$51,TRIM($A23),前提!$C$12:$C$51,"共通")+SUMIFS(前提!$L$12:$L$51,前提!$A$12:$A$51,TRIM($A23),前提!$C$12:$C$51,$B$3)) -> 0 | L23: =-$B$8*(SUMIFS(前提!$M$12:$M$51,前提!$A$12:$A$51,TRIM($A23),前提!$C$12:$C$51,"共通")+SUMIFS(前提!$M$12:$M$51,前提!$A$12:$A$51,TRIM($A23),前提!$C$12:$C$51,$B$3)) -> 0 | M23: =-$B$8*(SUMIFS(前提!$N$12:$N$51,前提!$A$12:$A$51,TRIM($A23),前提!$C$12:$C$51,"共通")+SUMIFS(前提!$N$12:$N$51,前提!$A$12:$A$51,TRIM($A23),前提!$C$12:$C$51,$B$3)) -> 0 | N23: =-$B$8*(SUMIFS(前提!$O$12:$O$51,前提!$A$12:$A$51,TRIM($A23),前提!$C$12:$C$51,"共通")+SUMIFS(前提!$O$12:$O$51,前提!$A$12:$A$51,TRIM($A23),前提!$C$12:$C$51,$B$3)) -> 0 | O23: =-$B$8*(SUMIFS(前提!$P$12:$P$51,前提!$A$12:$A$51,TRIM($A23),前提!$C$12:$C$51,"共通")+SUMIFS(前提!$P$12:$P$51,前提!$A$12:$A$51,TRIM($A23),前提!$C$12:$C$51,$B$3)) -> 0 | P23: =-$B$8*(SUMIFS(前提!$Q$12:$Q$51,前提!$A$12:$A$51,TRIM($A23),前提!$C$12:$C$51,"共通")+SUMIFS(前提!$Q$12:$Q$51,前提!$A$12:$A$51,TRIM($A23),前提!$C$12:$C$51,$B$3)) -> 0 | Q23: =-$B$8*(SUMIFS(前提!$R$12:$R$51,前提!$A$12:$A$51,TRIM($A23),前提!$C$12:$C$51,"共通")+SUMIFS(前提!$R$12:$R$51,前提!$A$12:$A$51,TRIM($A23),前提!$C$12:$C$51,$B$3)) -> 0 | R23: =-$B$8*(SUMIFS(前提!$S$12:$S$51,前提!$A$12:$A$51,TRIM($A23),前提!$C$12:$C$51,"共通")+SUMIFS(前提!$S$12:$S$51,前提!$A$12:$A$51,TRIM($A23),前提!$C$12:$C$51,$B$3)) -> 0 | S23: =SUM(C23:R23) -> -36.5
A24: クレッシェンド | C24: =-$B$9*(SUMIFS(前提!$D$12:$D$51,前提!$A$12:$A$51,TRIM($A24),前提!$C$12:$C$51,"共通")+SUMIFS(前提!$D$12:$D$51,前提!$A$12:$A$51,TRIM($A24),前提!$C$12:$C$51,$B$3)) -> 0 | D24: =-$B$9*(SUMIFS(前提!$E$12:$E$51,前提!$A$12:$A$51,TRIM($A24),前提!$C$12:$C$51,"共通")+SUMIFS(前提!$E$12:$E$51,前提!$A$12:$A$51,TRIM($A24),前提!$C$12:$C$51,$B$3)) -> -3.1 | E24: =-$B$9*(SUMIFS(前提!$F$12:$F$51,前提!$A$12:$A$51,TRIM($A24),前提!$C$12:$C$51,"共通")+SUMIFS(前提!$F$12:$F$51,前提!$A$12:$A$51,TRIM($A24),前提!$C$12:$C$51,$B$3)) -> -32 | F24: =-$B$9*(SUMIFS(前提!$G$12:$G$51,前提!$A$12:$A$51,TRIM($A24),前提!$C$12:$C$51,"共通")+SUMIFS(前提!$G$12:$G$51,前提!$A$12:$A$51,TRIM($A24),前提!$C$12:$C$51,$B$3)) -> 0 | G24: =-$B$9*(SUMIFS(前提!$H$12:$H$51,前提!$A$12:$A$51,TRIM($A24),前提!$C$12:$C$51,"共通")+SUMIFS(前提!$H$12:$H$51,前提!$A$12:$A$51,TRIM($A24),前提!$C$12:$C$51,$B$3)) -> 0 | H24: =-$B$9*(SUMIFS(前提!$I$12:$I$51,前提!$A$12:$A$51,TRIM($A24),前提!$C$12:$C$51,"共通")+SUMIFS(前提!$I$12:$I$51,前提!$A$12:$A$51,TRIM($A24),前提!$C$12:$C$51,$B$3)) -> 0 | I24: =-$B$9*(SUMIFS(前提!$J$12:$J$51,前提!$A$12:$A$51,TRIM($A24),前提!$C$12:$C$51,"共通")+SUMIFS(前提!$J$12:$J$51,前提!$A$12:$A$51,TRIM($A24),前提!$C$12:$C$51,$B$3)) -> 0 | J24: =-$B$9*(SUMIFS(前提!$K$12:$K$51,前提!$A$12:$A$51,TRIM($A24),前提!$C$12:$C$51,"共通")+SUMIFS(前提!$K$12:$K$51,前提!$A$12:$A$51,TRIM($A24),前提!$C$12:$C$51,$B$3)) -> 0 | K24: =-$B$9*(SUMIFS(前提!$L$12:$L$51,前提!$A$12:$A$51,TRIM($A24),前提!$C$12:$C$51,"共通")+SUMIFS(前提!$L$12:$L$51,前提!$A$12:$A$51,TRIM($A24),前提!$C$12:$C$51,$B$3)) -> 0 | L24: =-$B$9*(SUMIFS(前提!$M$12:$M$51,前提!$A$12:$A$51,TRIM($A24),前提!$C$12:$C$51,"共通")+SUMIFS(前提!$M$12:$M$51,前提!$A$12:$A$51,TRIM($A24),前提!$C$12:$C$51,$B$3)) -> 0 | M24: =-$B$9*(SUMIFS(前提!$N$12:$N$51,前提!$A$12:$A$51,TRIM($A24),前提!$C$12:$C$51,"共通")+SUMIFS(前提!$N$12:$N$51,前提!$A$12:$A$51,TRIM($A24),前提!$C$12:$C$51,$B$3)) -> 0 | N24: =-$B$9*(SUMIFS(前提!$O$12:$O$51,前提!$A$12:$A$51,TRIM($A24),前提!$C$12:$C$51,"共通")+SUMIFS(前提!$O$12:$O$51,前提!$A$12:$A$51,TRIM($A24),前提!$C$12:$C$51,$B$3)) -> 0 | O24: =-$B$9*(SUMIFS(前提!$P$12:$P$51,前提!$A$12:$A$51,TRIM($A24),前提!$C$12:$C$51,"共通")+SUMIFS(前提!$P$12:$P$51,前提!$A$12:$A$51,TRIM($A24),前提!$C$12:$C$51,$B$3)) -> 0 | P24: =-$B$9*(SUMIFS(前提!$Q$12:$Q$51,前提!$A$12:$A$51,TRIM($A24),前提!$C$12:$C$51,"共通")+SUMIFS(前提!$Q$12:$Q$51,前提!$A$12:$A$51,TRIM($A24),前提!$C$12:$C$51,$B$3)) -> 0 | Q24: =-$B$9*(SUMIFS(前提!$R$12:$R$51,前提!$A$12:$A$51,TRIM($A24),前提!$C$12:$C$51,"共通")+SUMIFS(前提!$R$12:$R$51,前提!$A$12:$A$51,TRIM($A24),前提!$C$12:$C$51,$B$3)) -> 0 | R24: =-$B$9*(SUMIFS(前提!$S$12:$S$51,前提!$A$12:$A$51,TRIM($A24),前提!$C$12:$C$51,"共通")+SUMIFS(前提!$S$12:$S$51,前提!$A$12:$A$51,TRIM($A24),前提!$C$12:$C$51,$B$3)) -> 0 | S24: =SUM(C24:R24) -> -35.1
A25: ワイズケア | C25: =-$B$10*(SUMIFS(前提!$D$12:$D$51,前提!$A$12:$A$51,TRIM($A25),前提!$C$12:$C$51,"共通")+SUMIFS(前提!$D$12:$D$51,前提!$A$12:$A$51,TRIM($A25),前提!$C$12:$C$51,$B$3)) -> 0 | D25: =-$B$10*(SUMIFS(前提!$E$12:$E$51,前提!$A$12:$A$51,TRIM($A25),前提!$C$12:$C$51,"共通")+SUMIFS(前提!$E$12:$E$51,前提!$A$12:$A$51,TRIM($A25),前提!$C$12:$C$51,$B$3)) -> 0 | E25: =-$B$10*(SUMIFS(前提!$F$12:$F$51,前提!$A$12:$A$51,TRIM($A25),前提!$C$12:$C$51,"共通")+SUMIFS(前提!$F$12:$F$51,前提!$A$12:$A$51,TRIM($A25),前提!$C$12:$C$51,$B$3)) -> 0 | F25: =-$B$10*(SUMIFS(前提!$G$12:$G$51,前提!$A$12:$A$51,TRIM($A25),前提!$C$12:$C$51,"共通")+SUMIFS(前提!$G$12:$G$51,前提!$A$12:$A$51,TRIM($A25),前提!$C$12:$C$51,$B$3)) -> 0 | G25: =-$B$10*(SUMIFS(前提!$H$12:$H$51,前提!$A$12:$A$51,TRIM($A25),前提!$C$12:$C$51,"共通")+SUMIFS(前提!$H$12:$H$51,前提!$A$12:$A$51,TRIM($A25),前提!$C$12:$C$51,$B$3)) -> 0 | H25: =-$B$10*(SUMIFS(前提!$I$12:$I$51,前提!$A$12:$A$51,TRIM($A25),前提!$C$12:$C$51,"共通")+SUMIFS(前提!$I$12:$I$51,前提!$A$12:$A$51,TRIM($A25),前提!$C$12:$C$51,$B$3)) -> 0 | I25: =-$B$10*(SUMIFS(前提!$J$12:$J$51,前提!$A$12:$A$51,TRIM($A25),前提!$C$12:$C$51,"共通")+SUMIFS(前提!$J$12:$J$51,前提!$A$12:$A$51,TRIM($A25),前提!$C$12:$C$51,$B$3)) -> 0 | J25: =-$B$10*(SUMIFS(前提!$K$12:$K$51,前提!$A$12:$A$51,TRIM($A25),前提!$C$12:$C$51,"共通")+SUMIFS(前提!$K$12:$K$51,前提!$A$12:$A$51,TRIM($A25),前提!$C$12:$C$51,$B$3)) -> 0 | K25: =-$B$10*(SUMIFS(前提!$L$12:$L$51,前提!$A$12:$A$51,TRIM($A25),前提!$C$12:$C$51,"共通")+SUMIFS(前提!$L$12:$L$51,前提!$A$12:$A$51,TRIM($A25),前提!$C$12:$C$51,$B$3)) -> 0 | L25: =-$B$10*(SUMIFS(前提!$M$12:$M$51,前提!$A$12:$A$51,TRIM($A25),前提!$C$12:$C$51,"共通")+SUMIFS(前提!$M$12:$M$51,前提!$A$12:$A$51,TRIM($A25),前提!$C$12:$C$51,$B$3)) -> 0 | M25: =-$B$10*(SUMIFS(前提!$N$12:$N$51,前提!$A$12:$A$51,TRIM($A25),前提!$C$12:$C$51,"共通")+SUMIFS(前提!$N$12:$N$51,前提!$A$12:$A$51,TRIM($A25),前提!$C$12:$C$51,$B$3)) -> 0 | N25: =-$B$10*(SUMIFS(前提!$O$12:$O$51,前提!$A$12:$A$51,TRIM($A25),前提!$C$12:$C$51,"共通")+SUMIFS(前提!$O$12:$O$51,前提!$A$12:$A$51,TRIM($A25),前提!$C$12:$C$51,$B$3)) -> 0 | O25: =-$B$10*(SUMIFS(前提!$P$12:$P$51,前提!$A$12:$A$51,TRIM($A25),前提!$C$12:$C$51,"共通")+SUMIFS(前提!$P$12:$P$51,前提!$A$12:$A$51,TRIM($A25),前提!$C$12:$C$51,$B$3)) -> 0 | P25: =-$B$10*(SUMIFS(前提!$Q$12:$Q$51,前提!$A$12:$A$51,TRIM($A25),前提!$C$12:$C$51,"共通")+SUMIFS(前提!$Q$12:$Q$51,前提!$A$12:$A$51,TRIM($A25),前提!$C$12:$C$51,$B$3)) -> 0 | Q25: =-$B$10*(SUMIFS(前提!$R$12:$R$51,前提!$A$12:$A$51,TRIM($A25),前提!$C$12:$C$51,"共通")+SUMIFS(前提!$R$12:$R$51,前提!$A$12:$A$51,TRIM($A25),前提!$C$12:$C$51,$B$3)) -> 0 | R25: =-$B$10*(SUMIFS(前提!$S$12:$S$51,前提!$A$12:$A$51,TRIM($A25),前提!$C$12:$C$51,"共通")+SUMIFS(前提!$S$12:$S$51,前提!$A$12:$A$51,TRIM($A25),前提!$C$12:$C$51,$B$3)) -> 0 | S25: =SUM(C25:R25) -> 0
A26: エーステイスト | C26: =-$B$11*(SUMIFS(前提!$D$12:$D$51,前提!$A$12:$A$51,TRIM($A26),前提!$C$12:$C$51,"共通")+SUMIFS(前提!$D$12:$D$51,前提!$A$12:$A$51,TRIM($A26),前提!$C$12:$C$51,$B$3)) -> 0 | D26: =-$B$11*(SUMIFS(前提!$E$12:$E$51,前提!$A$12:$A$51,TRIM($A26),前提!$C$12:$C$51,"共通")+SUMIFS(前提!$E$12:$E$51,前提!$A$12:$A$51,TRIM($A26),前提!$C$12:$C$51,$B$3)) -> 0 | E26: =-$B$11*(SUMIFS(前提!$F$12:$F$51,前提!$A$12:$A$51,TRIM($A26),前提!$C$12:$C$51,"共通")+SUMIFS(前提!$F$12:$F$51,前提!$A$12:$A$51,TRIM($A26),前提!$C$12:$C$51,$B$3)) -> 0 | F26: =-$B$11*(SUMIFS(前提!$G$12:$G$51,前提!$A$12:$A$51,TRIM($A26),前提!$C$12:$C$51,"共通")+SUMIFS(前提!$G$12:$G$51,前提!$A$12:$A$51,TRIM($A26),前提!$C$12:$C$51,$B$3)) -> 0 | G26: =-$B$11*(SUMIFS(前提!$H$12:$H$51,前提!$A$12:$A$51,TRIM($A26),前提!$C$12:$C$51,"共通")+SUMIFS(前提!$H$12:$H$51,前提!$A$12:$A$51,TRIM($A26),前提!$C$12:$C$51,$B$3)) -> 0 | H26: =-$B$11*(SUMIFS(前提!$I$12:$I$51,前提!$A$12:$A$51,TRIM($A26),前提!$C$12:$C$51,"共通")+SUMIFS(前提!$I$12:$I$51,前提!$A$12:$A$51,TRIM($A26),前提!$C$12:$C$51,$B$3)) -> 0 | I26: =-$B$11*(SUMIFS(前提!$J$12:$J$51,前提!$A$12:$A$51,TRIM($A26),前提!$C$12:$C$51,"共通")+SUMIFS(前提!$J$12:$J$51,前提!$A$12:$A$51,TRIM($A26),前提!$C$12:$C$51,$B$3)) -> 0 | J26: =-$B$11*(SUMIFS(前提!$K$12:$K$51,前提!$A$12:$A$51,TRIM($A26),前提!$C$12:$C$51,"共通")+SUMIFS(前提!$K$12:$K$51,前提!$A$12:$A$51,TRIM($A26),前提!$C$12:$C$51,$B$3)) -> 0 | K26: =-$B$11*(SUMIFS(前提!$L$12:$L$51,前提!$A$12:$A$51,TRIM($A26),前提!$C$12:$C$51,"共通")+SUMIFS(前提!$L$12:$L$51,前提!$A$12:$A$51,TRIM($A26),前提!$C$12:$C$51,$B$3)) -> 0 | L26: =-$B$11*(SUMIFS(前提!$M$12:$M$51,前提!$A$12:$A$51,TRIM($A26),前提!$C$12:$C$51,"共通")+SUMIFS(前提!$M$12:$M$51,前提!$A$12:$A$51,TRIM($A26),前提!$C$12:$C$51,$B$3)) -> 0 | M26: =-$B$11*(SUMIFS(前提!$N$12:$N$51,前提!$A$12:$A$51,TRIM($A26),前提!$C$12:$C$51,"共通")+SUMIFS(前提!$N$12:$N$51,前提!$A$12:$A$51,TRIM($A26),前提!$C$12:$C$51,$B$3)) -> 0 | N26: =-$B$11*(SUMIFS(前提!$O$12:$O$51,前提!$A$12:$A$51,TRIM($A26),前提!$C$12:$C$51,"共通")+SUMIFS(前提!$O$12:$O$51,前提!$A$12:$A$51,TRIM($A26),前提!$C$12:$C$51,$B$3)) -> 0 | O26: =-$B$11*(SUMIFS(前提!$P$12:$P$51,前提!$A$12:$A$51,TRIM($A26),前提!$C$12:$C$51,"共通")+SUMIFS(前提!$P$12:$P$51,前提!$A$12:$A$51,TRIM($A26),前提!$C$12:$C$51,$B$3)) -> 0 | P26: =-$B$11*(SUMIFS(前提!$Q$12:$Q$51,前提!$A$12:$A$51,TRIM($A26),前提!$C$12:$C$51,"共通")+SUMIFS(前提!$Q$12:$Q$51,前提!$A$12:$A$51,TRIM($A26),前提!$C$12:$C$51,$B$3)) -> 0 | Q26: =-$B$11*(SUMIFS(前提!$R$12:$R$51,前提!$A$12:$A$51,TRIM($A26),前提!$C$12:$C$51,"共通")+SUMIFS(前提!$R$12:$R$51,前提!$A$12:$A$51,TRIM($A26),前提!$C$12:$C$51,$B$3)) -> 0 | R26: =-$B$11*(SUMIFS(前提!$S$12:$S$51,前提!$A$12:$A$51,TRIM($A26),前提!$C$12:$C$51,"共通")+SUMIFS(前提!$S$12:$S$51,前提!$A$12:$A$51,TRIM($A26),前提!$C$12:$C$51,$B$3)) -> 0 | S26: =SUM(C26:R26) -> 0
A27: 日本経営センター | C27: =-$B$12*(SUMIFS(前提!$D$12:$D$51,前提!$A$12:$A$51,TRIM($A27),前提!$C$12:$C$51,"共通")+SUMIFS(前提!$D$12:$D$51,前提!$A$12:$A$51,TRIM($A27),前提!$C$12:$C$51,$B$3)) -> 0 | D27: =-$B$12*(SUMIFS(前提!$E$12:$E$51,前提!$A$12:$A$51,TRIM($A27),前提!$C$12:$C$51,"共通")+SUMIFS(前提!$E$12:$E$51,前提!$A$12:$A$51,TRIM($A27),前提!$C$12:$C$51,$B$3)) -> 0 | E27: =-$B$12*(SUMIFS(前提!$F$12:$F$51,前提!$A$12:$A$51,TRIM($A27),前提!$C$12:$C$51,"共通")+SUMIFS(前提!$F$12:$F$51,前提!$A$12:$A$51,TRIM($A27),前提!$C$12:$C$51,$B$3)) -> 0 | F27: =-$B$12*(SUMIFS(前提!$G$12:$G$51,前提!$A$12:$A$51,TRIM($A27),前提!$C$12:$C$51,"共通")+SUMIFS(前提!$G$12:$G$51,前提!$A$12:$A$51,TRIM($A27),前提!$C$12:$C$51,$B$3)) -> 0 | G27: =-$B$12*(SUMIFS(前提!$H$12:$H$51,前提!$A$12:$A$51,TRIM($A27),前提!$C$12:$C$51,"共通")+SUMIFS(前提!$H$12:$H$51,前提!$A$12:$A$51,TRIM($A27),前提!$C$12:$C$51,$B$3)) -> 0 | H27: =-$B$12*(SUMIFS(前提!$I$12:$I$51,前提!$A$12:$A$51,TRIM($A27),前提!$C$12:$C$51,"共通")+SUMIFS(前提!$I$12:$I$51,前提!$A$12:$A$51,TRIM($A27),前提!$C$12:$C$51,$B$3)) -> 0 | I27: =-$B$12*(SUMIFS(前提!$J$12:$J$51,前提!$A$12:$A$51,TRIM($A27),前提!$C$12:$C$51,"共通")+SUMIFS(前提!$J$12:$J$51,前提!$A$12:$A$51,TRIM($A27),前提!$C$12:$C$51,$B$3)) -> 0 | J27: =-$B$12*(SUMIFS(前提!$K$12:$K$51,前提!$A$12:$A$51,TRIM($A27),前提!$C$12:$C$51,"共通")+SUMIFS(前提!$K$12:$K$51,前提!$A$12:$A$51,TRIM($A27),前提!$C$12:$C$51,$B$3)) -> 0 | K27: =-$B$12*(SUMIFS(前提!$L$12:$L$51,前提!$A$12:$A$51,TRIM($A27),前提!$C$12:$C$51,"共通")+SUMIFS(前提!$L$12:$L$51,前提!$A$12:$A$51,TRIM($A27),前提!$C$12:$C$51,$B$3)) -> 0 | L27: =-$B$12*(SUMIFS(前提!$M$12:$M$51,前提!$A$12:$A$51,TRIM($A27),前提!$C$12:$C$51,"共通")+SUMIFS(前提!$M$12:$M$51,前提!$A$12:$A$51,TRIM($A27),前提!$C$12:$C$51,$B$3)) -> 0 | M27: =-$B$12*(SUMIFS(前提!$N$12:$N$51,前提!$A$12:$A$51,TRIM($A27),前提!$C$12:$C$51,"共通")+SUMIFS(前提!$N$12:$N$51,前提!$A$12:$A$51,TRIM($A27),前提!$C$12:$C$51,$B$3)) -> 0 | N27: =-$B$12*(SUMIFS(前提!$O$12:$O$51,前提!$A$12:$A$51,TRIM($A27),前提!$C$12:$C$51,"共通")+SUMIFS(前提!$O$12:$O$51,前提!$A$12:$A$51,TRIM($A27),前提!$C$12:$C$51,$B$3)) -> 0 | O27: =-$B$12*(SUMIFS(前提!$P$12:$P$51,前提!$A$12:$A$51,TRIM($A27),前提!$C$12:$C$51,"共通")+SUMIFS(前提!$P$12:$P$51,前提!$A$12:$A$51,TRIM($A27),前提!$C$12:$C$51,$B$3)) -> 0 | P27: =-$B$12*(SUMIFS(前提!$Q$12:$Q$51,前提!$A$12:$A$51,TRIM($A27),前提!$C$12:$C$51,"共通")+SUMIFS(前提!$Q$12:$Q$51,前提!$A$12:$A$51,TRIM($A27),前提!$C$12:$C$51,$B$3)) -> 0 | Q27: =-$B$12*(SUMIFS(前提!$R$12:$R$51,前提!$A$12:$A$51,TRIM($A27),前提!$C$12:$C$51,"共通")+SUMIFS(前提!$R$12:$R$51,前提!$A$12:$A$51,TRIM($A27),前提!$C$12:$C$51,$B$3)) -> 0 | R27: =-$B$12*(SUMIFS(前提!$S$12:$S$51,前提!$A$12:$A$51,TRIM($A27),前提!$C$12:$C$51,"共通")+SUMIFS(前提!$S$12:$S$51,前提!$A$12:$A$51,TRIM($A27),前提!$C$12:$C$51,$B$3)) -> 0 | S27: =SUM(C27:R27) -> 0
A28: セレサ | C28: =-$B$13*(SUMIFS(前提!$D$12:$D$51,前提!$A$12:$A$51,TRIM($A28),前提!$C$12:$C$51,"共通")+SUMIFS(前提!$D$12:$D$51,前提!$A$12:$A$51,TRIM($A28),前提!$C$12:$C$51,$B$3)) -> 0 | D28: =-$B$13*(SUMIFS(前提!$E$12:$E$51,前提!$A$12:$A$51,TRIM($A28),前提!$C$12:$C$51,"共通")+SUMIFS(前提!$E$12:$E$51,前提!$A$12:$A$51,TRIM($A28),前提!$C$12:$C$51,$B$3)) -> 0 | E28: =-$B$13*(SUMIFS(前提!$F$12:$F$51,前提!$A$12:$A$51,TRIM($A28),前提!$C$12:$C$51,"共通")+SUMIFS(前提!$F$12:$F$51,前提!$A$12:$A$51,TRIM($A28),前提!$C$12:$C$51,$B$3)) -> 0 | F28: =-$B$13*(SUMIFS(前提!$G$12:$G$51,前提!$A$12:$A$51,TRIM($A28),前提!$C$12:$C$51,"共通")+SUMIFS(前提!$G$12:$G$51,前提!$A$12:$A$51,TRIM($A28),前提!$C$12:$C$51,$B$3)) -> 0 | G28: =-$B$13*(SUMIFS(前提!$H$12:$H$51,前提!$A$12:$A$51,TRIM($A28),前提!$C$12:$C$51,"共通")+SUMIFS(前提!$H$12:$H$51,前提!$A$12:$A$51,TRIM($A28),前提!$C$12:$C$51,$B$3)) -> 0 | H28: =-$B$13*(SUMIFS(前提!$I$12:$I$51,前提!$A$12:$A$51,TRIM($A28),前提!$C$12:$C$51,"共通")+SUMIFS(前提!$I$12:$I$51,前提!$A$12:$A$51,TRIM($A28),前提!$C$12:$C$51,$B$3)) -> 0 | I28: =-$B$13*(SUMIFS(前提!$J$12:$J$51,前提!$A$12:$A$51,TRIM($A28),前提!$C$12:$C$51,"共通")+SUMIFS(前提!$J$12:$J$51,前提!$A$12:$A$51,TRIM($A28),前提!$C$12:$C$51,$B$3)) -> 0 | J28: =-$B$13*(SUMIFS(前提!$K$12:$K$51,前提!$A$12:$A$51,TRIM($A28),前提!$C$12:$C$51,"共通")+SUMIFS(前提!$K$12:$K$51,前提!$A$12:$A$51,TRIM($A28),前提!$C$12:$C$51,$B$3)) -> 0 | K28: =-$B$13*(SUMIFS(前提!$L$12:$L$51,前提!$A$12:$A$51,TRIM($A28),前提!$C$12:$C$51,"共通")+SUMIFS(前提!$L$12:$L$51,前提!$A$12:$A$51,TRIM($A28),前提!$C$12:$C$51,$B$3)) -> 0 | L28: =-$B$13*(SUMIFS(前提!$M$12:$M$51,前提!$A$12:$A$51,TRIM($A28),前提!$C$12:$C$51,"共通")+SUMIFS(前提!$M$12:$M$51,前提!$A$12:$A$51,TRIM($A28),前提!$C$12:$C$51,$B$3)) -> 0 | M28: =-$B$13*(SUMIFS(前提!$N$12:$N$51,前提!$A$12:$A$51,TRIM($A28),前提!$C$12:$C$51,"共通")+SUMIFS(前提!$N$12:$N$51,前提!$A$12:$A$51,TRIM($A28),前提!$C$12:$C$51,$B$3)) -> 0 | N28: =-$B$13*(SUMIFS(前提!$O$12:$O$51,前提!$A$12:$A$51,TRIM($A28),前提!$C$12:$C$51,"共通")+SUMIFS(前提!$O$12:$O$51,前提!$A$12:$A$51,TRIM($A28),前提!$C$12:$C$51,$B$3)) -> 0 | O28: =-$B$13*(SUMIFS(前提!$P$12:$P$51,前提!$A$12:$A$51,TRIM($A28),前提!$C$12:$C$51,"共通")+SUMIFS(前提!$P$12:$P$51,前提!$A$12:$A$51,TRIM($A28),前提!$C$12:$C$51,$B$3)) -> 0 | P28: =-$B$13*(SUMIFS(前提!$Q$12:$Q$51,前提!$A$12:$A$51,TRIM($A28),前提!$C$12:$C$51,"共通")+SUMIFS(前提!$Q$12:$Q$51,前提!$A$12:$A$51,TRIM($A28),前提!$C$12:$C$51,$B$3)) -> 0 | Q28: =-$B$13*(SUMIFS(前提!$R$12:$R$51,前提!$A$12:$A$51,TRIM($A28),前提!$C$12:$C$51,"共通")+SUMIFS(前提!$R$12:$R$51,前提!$A$12:$A$51,TRIM($A28),前提!$C$12:$C$51,$B$3)) -> 0 | R28: =-$B$13*(SUMIFS(前提!$S$12:$S$51,前提!$A$12:$A$51,TRIM($A28),前提!$C$12:$C$51,"共通")+SUMIFS(前提!$S$12:$S$51,前提!$A$12:$A$51,TRIM($A28),前提!$C$12:$C$51,$B$3)) -> 0 | S28: =SUM(C28:R28) -> 0
A29: シルバーメディカル | C29: =-$B$14*(SUMIFS(前提!$D$12:$D$51,前提!$A$12:$A$51,TRIM($A29),前提!$C$12:$C$51,"共通")+SUMIFS(前提!$D$12:$D$51,前提!$A$12:$A$51,TRIM($A29),前提!$C$12:$C$51,$B$3)) -> 0 | D29: =-$B$14*(SUMIFS(前提!$E$12:$E$51,前提!$A$12:$A$51,TRIM($A29),前提!$C$12:$C$51,"共通")+SUMIFS(前提!$E$12:$E$51,前提!$A$12:$A$51,TRIM($A29),前提!$C$12:$C$51,$B$3)) -> -1.1 | E29: =-$B$14*(SUMIFS(前提!$F$12:$F$51,前提!$A$12:$A$51,TRIM($A29),前提!$C$12:$C$51,"共通")+SUMIFS(前提!$F$12:$F$51,前提!$A$12:$A$51,TRIM($A29),前提!$C$12:$C$51,$B$3)) -> -5 | F29: =-$B$14*(SUMIFS(前提!$G$12:$G$51,前提!$A$12:$A$51,TRIM($A29),前提!$C$12:$C$51,"共通")+SUMIFS(前提!$G$12:$G$51,前提!$A$12:$A$51,TRIM($A29),前提!$C$12:$C$51,$B$3)) -> -114 | G29: =-$B$14*(SUMIFS(前提!$H$12:$H$51,前提!$A$12:$A$51,TRIM($A29),前提!$C$12:$C$51,"共通")+SUMIFS(前提!$H$12:$H$51,前提!$A$12:$A$51,TRIM($A29),前提!$C$12:$C$51,$B$3)) -> 0 | H29: =-$B$14*(SUMIFS(前提!$I$12:$I$51,前提!$A$12:$A$51,TRIM($A29),前提!$C$12:$C$51,"共通")+SUMIFS(前提!$I$12:$I$51,前提!$A$12:$A$51,TRIM($A29),前提!$C$12:$C$51,$B$3)) -> 0 | I29: =-$B$14*(SUMIFS(前提!$J$12:$J$51,前提!$A$12:$A$51,TRIM($A29),前提!$C$12:$C$51,"共通")+SUMIFS(前提!$J$12:$J$51,前提!$A$12:$A$51,TRIM($A29),前提!$C$12:$C$51,$B$3)) -> 0 | J29: =-$B$14*(SUMIFS(前提!$K$12:$K$51,前提!$A$12:$A$51,TRIM($A29),前提!$C$12:$C$51,"共通")+SUMIFS(前提!$K$12:$K$51,前提!$A$12:$A$51,TRIM($A29),前提!$C$12:$C$51,$B$3)) -> 0 | K29: =-$B$14*(SUMIFS(前提!$L$12:$L$51,前提!$A$12:$A$51,TRIM($A29),前提!$C$12:$C$51,"共通")+SUMIFS(前提!$L$12:$L$51,前提!$A$12:$A$51,TRIM($A29),前提!$C$12:$C$51,$B$3)) -> 0 | L29: =-$B$14*(SUMIFS(前提!$M$12:$M$51,前提!$A$12:$A$51,TRIM($A29),前提!$C$12:$C$51,"共通")+SUMIFS(前提!$M$12:$M$51,前提!$A$12:$A$51,TRIM($A29),前提!$C$12:$C$51,$B$3)) -> 0 | M29: =-$B$14*(SUMIFS(前提!$N$12:$N$51,前提!$A$12:$A$51,TRIM($A29),前提!$C$12:$C$51,"共通")+SUMIFS(前提!$N$12:$N$51,前提!$A$12:$A$51,TRIM($A29),前提!$C$12:$C$51,$B$3)) -> 0 | N29: =-$B$14*(SUMIFS(前提!$O$12:$O$51,前提!$A$12:$A$51,TRIM($A29),前提!$C$12:$C$51,"共通")+SUMIFS(前提!$O$12:$O$51,前提!$A$12:$A$51,TRIM($A29),前提!$C$12:$C$51,$B$3)) -> 0 | O29: =-$B$14*(SUMIFS(前提!$P$12:$P$51,前提!$A$12:$A$51,TRIM($A29),前提!$C$12:$C$51,"共通")+SUMIFS(前提!$P$12:$P$51,前提!$A$12:$A$51,TRIM($A29),前提!$C$12:$C$51,$B$3)) -> 0 | P29: =-$B$14*(SUMIFS(前提!$Q$12:$Q$51,前提!$A$12:$A$51,TRIM($A29),前提!$C$12:$C$51,"共通")+SUMIFS(前提!$Q$12:$Q$51,前提!$A$12:$A$51,TRIM($A29),前提!$C$12:$C$51,$B$3)) -> 0 | Q29: =-$B$14*(SUMIFS(前提!$R$12:$R$51,前提!$A$12:$A$51,TRIM($A29),前提!$C$12:$C$51,"共通")+SUMIFS(前提!$R$12:$R$51,前提!$A$12:$A$51,TRIM($A29),前提!$C$12:$C$51,$B$3)) -> 0 | R29: =-$B$14*(SUMIFS(前提!$S$12:$S$51,前提!$A$12:$A$51,TRIM($A29),前提!$C$12:$C$51,"共通")+SUMIFS(前提!$S$12:$S$51,前提!$A$12:$A$51,TRIM($A29),前提!$C$12:$C$51,$B$3)) -> 0 | S29: =SUM(C29:R29) -> -120.1
A30: 案件支出 合計 | C30: =SUM(C21:C29) -> -30 | D30: =SUM(D21:D29) -> -18.2 | E30: =SUM(E21:E29) -> -67.5 | F30: =SUM(F21:F29) -> -126 | G30: =SUM(G21:G29) -> 0 | H30: =SUM(H21:H29) -> 0 | I30: =SUM(I21:I29) -> -12 | J30: =SUM(J21:J29) -> 0 | ... R30: =SUM(R21:R29) -> 0 | S30: =SUM(C30:R30) -> -253.7
A31: 期末現預金 | C31: =C18+C19+C30 -> 329.3 | D31: =D18+D19+D30 -> 304.1 | E31: =E18+E19+E30 -> 229.6 | F31: =F18+F19+F30 -> 96.6 | G31: =G18+G19+G30 -> 91.6 | H31: =H18+H19+H30 -> 86.6 | I31: =I18+I19+I30 -> 69.6 | J31: =J18+J19+J30 -> 64.6 | ... R31: =R18+R19+R30 -> 24.6
A32: 安全水準との差 | C32: =C31-前提!$B$4 -> 229.3 | D32: =D31-前提!$B$4 -> 204.1 | E32: =E31-前提!$B$4 -> 129.6 | F32: =F31-前提!$B$4 -> -3.4 | G32: =G31-前提!$B$4 -> -8.4 | H32: =H31-前提!$B$4 -> -13.4 | I32: =I31-前提!$B$4 -> -30.4 | J32: =J31-前提!$B$4 -> -35.4 | ... R32: =R31-前提!$B$4 -> -75.4
A33: 必要調達額（安全水準を維持するための不足額） | C33: =MAX(0,前提!$B$4-C31) -> 0 | D33: =MAX(0,前提!$B$4-D31) -> 0 | E33: =MAX(0,前提!$B$4-E31) -> 0 | F33: =MAX(0,前提!$B$4-F31) -> 3.4 | G33: =MAX(0,前提!$B$4-G31) -> 8.4 | H33: =MAX(0,前提!$B$4-H31) -> 13.4 | I33: =MAX(0,前提!$B$4-I31) -> 30.4 | J33: =MAX(0,前提!$B$4-J31) -> 35.4 | ... R33: =MAX(0,前提!$B$4-R31) -> 75.4
A34: 累計案件支出 | C34: =-SUM($C30:C30) -> 30 | D34: =-SUM($C30:D30) -> 48.2 | E34: =-SUM($C30:E30) -> 115.7 | F34: =-SUM($C30:F30) -> 241.7 | G34: =-SUM($C30:G30) -> 241.7 | H34: =-SUM($C30:H30) -> 241.7 | I34: =-SUM($C30:I30) -> 253.7 | J34: =-SUM($C30:J30) -> 253.7 | ... R34: =-SUM($C30:R30) -> 253.7
A35: 安全水準割込み（1＝割込） | C35: =IF(C31<前提!$B$4,1,0) -> 0 | D35: =IF(D31<前提!$B$4,1,0) -> 0 | E35: =IF(E31<前提!$B$4,1,0) -> 0 | F35: =IF(F31<前提!$B$4,1,0) -> 1 | G35: =IF(G31<前提!$B$4,1,0) -> 1 | H35: =IF(H31<前提!$B$4,1,0) -> 1 | I35: =IF(I31<前提!$B$4,1,0) -> 1 | J35: =IF(J31<前提!$B$4,1,0) -> 1 | ... R35: =IF(R31<前提!$B$4,1,0) -> 1
A37: Net Debt Capacity（連結・調達前）
A38: 売掛金（既存＋クロージング後の案件） | C38: =前提!$B$60+SUMPRODUCT($B$6:$B$14,案件一覧!$N$4:$N$12,--(案件一覧!$M$4:$M$12<=1)) -> 192 | D38: =前提!$B$60+SUMPRODUCT($B$6:$B$14,案件一覧!$N$4:$N$12,--(案件一覧!$M$4:$M$12<=2)) -> 192 | E38: =前提!$B$60+SUMPRODUCT($B$6:$B$14,案件一覧!$N$4:$N$12,--(案件一覧!$M$4:$M$12<=3)) -> 233 | F38: =前提!$B$60+SUMPRODUCT($B$6:$B$14,案件一覧!$N$4:$N$12,--(案件一覧!$M$4:$M$12<=4)) -> 393 | G38: =前提!$B$60+SUMPRODUCT($B$6:$B$14,案件一覧!$N$4:$N$12,--(案件一覧!$M$4:$M$12<=5)) -> 393 | H38: =前提!$B$60+SUMPRODUCT($B$6:$B$14,案件一覧!$N$4:$N$12,--(案件一覧!$M$4:$M$12<=6)) -> 393 | I38: =前提!$B$60+SUMPRODUCT($B$6:$B$14,案件一覧!$N$4:$N$12,--(案件一覧!$M$4:$M$12<=7)) -> 393 | J38: =前提!$B$60+SUMPRODUCT($B$6:$B$14,案件一覧!$N$4:$N$12,--(案件一覧!$M$4:$M$12<=8)) -> 393 | K38: =前提!$B$60+SUMPRODUCT($B$6:$B$14,案件一覧!$N$4:$N$12,--(案件一覧!$M$4:$M$12<=9)) -> 393 | L38: =前提!$B$60+SUMPRODUCT($B$6:$B$14,案件一覧!$N$4:$N$12,--(案件一覧!$M$4:$M$12<=10)) -> 393 | M38: =前提!$B$60+SUMPRODUCT($B$6:$B$14,案件一覧!$N$4:$N$12,--(案件一覧!$M$4:$M$12<=11)) -> 393 | N38: =前提!$B$60+SUMPRODUCT($B$6:$B$14,案件一覧!$N$4:$N$12,--(案件一覧!$M$4:$M$12<=12)) -> 393 | O38: =前提!$B$60+SUMPRODUCT($B$6:$B$14,案件一覧!$N$4:$N$12,--(案件一覧!$M$4:$M$12<=13)) -> 393 | P38: =前提!$B$60+SUMPRODUCT($B$6:$B$14,案件一覧!$N$4:$N$12,--(案件一覧!$M$4:$M$12<=14)) -> 393 | Q38: =前提!$B$60+SUMPRODUCT($B$6:$B$14,案件一覧!$N$4:$N$12,--(案件一覧!$M$4:$M$12<=15)) -> 393 | R38: =前提!$B$60+SUMPRODUCT($B$6:$B$14,案件一覧!$N$4:$N$12,--(案件一覧!$M$4:$M$12<=16)) -> 393
A39: 現預金（HD＋HT＋案件の残置現金） | C39: =C31+前提!D$57+SUMPRODUCT($B$6:$B$14,案件一覧!$O$4:$O$12,--(案件一覧!$M$4:$M$12<=1)) -> 405.3 | D39: =D31+前提!E$57+SUMPRODUCT($B$6:$B$14,案件一覧!$O$4:$O$12,--(案件一覧!$M$4:$M$12<=2)) -> 380.1 | E39: =E31+前提!F$57+SUMPRODUCT($B$6:$B$14,案件一覧!$O$4:$O$12,--(案件一覧!$M$4:$M$12<=3)) -> 333.6 | F39: =F31+前提!G$57+SUMPRODUCT($B$6:$B$14,案件一覧!$O$4:$O$12,--(案件一覧!$M$4:$M$12<=4)) -> 230.6 | G39: =G31+前提!H$57+SUMPRODUCT($B$6:$B$14,案件一覧!$O$4:$O$12,--(案件一覧!$M$4:$M$12<=5)) -> 229.6 | H39: =H31+前提!I$57+SUMPRODUCT($B$6:$B$14,案件一覧!$O$4:$O$12,--(案件一覧!$M$4:$M$12<=6)) -> 224.6 | I39: =I31+前提!J$57+SUMPRODUCT($B$6:$B$14,案件一覧!$O$4:$O$12,--(案件一覧!$M$4:$M$12<=7)) -> 207.6 | J39: =J31+前提!K$57+SUMPRODUCT($B$6:$B$14,案件一覧!$O$4:$O$12,--(案件一覧!$M$4:$M$12<=8)) -> 202.6 | K39: =K31+前提!L$57+SUMPRODUCT($B$6:$B$14,案件一覧!$O$4:$O$12,--(案件一覧!$M$4:$M$12<=9)) -> 197.6 | L39: =L31+前提!M$57+SUMPRODUCT($B$6:$B$14,案件一覧!$O$4:$O$12,--(案件一覧!$M$4:$M$12<=10)) -> 192.6 | M39: =M31+前提!N$57+SUMPRODUCT($B$6:$B$14,案件一覧!$O$4:$O$12,--(案件一覧!$M$4:$M$12<=11)) -> 187.6 | N39: =N31+前提!O$57+SUMPRODUCT($B$6:$B$14,案件一覧!$O$4:$O$12,--(案件一覧!$M$4:$M$12<=12)) -> 182.6 | O39: =O31+前提!P$57+SUMPRODUCT($B$6:$B$14,案件一覧!$O$4:$O$12,--(案件一覧!$M$4:$M$12<=13)) -> 177.6 | P39: =P31+前提!Q$57+SUMPRODUCT($B$6:$B$14,案件一覧!$O$4:$O$12,--(案件一覧!$M$4:$M$12<=14)) -> 172.6 | Q39: =Q31+前提!R$57+SUMPRODUCT($B$6:$B$14,案件一覧!$O$4:$O$12,--(案件一覧!$M$4:$M$12<=15)) -> 167.6 | R39: =R31+前提!S$57+SUMPRODUCT($B$6:$B$14,案件一覧!$O$4:$O$12,--(案件一覧!$M$4:$M$12<=16)) -> 162.6
A40: 調整後EBITDA年換算（オーガニック＋案件現状値） | C40: =前提!D$56+SUMPRODUCT($B$6:$B$14,案件一覧!$E$4:$E$12,--(案件一覧!$M$4:$M$12<=1)) -> 32 | D40: =前提!E$56+SUMPRODUCT($B$6:$B$14,案件一覧!$E$4:$E$12,--(案件一覧!$M$4:$M$12<=2)) -> 34 | E40: =前提!F$56+SUMPRODUCT($B$6:$B$14,案件一覧!$E$4:$E$12,--(案件一覧!$M$4:$M$12<=3)) -> 75 | F40: =前提!G$56+SUMPRODUCT($B$6:$B$14,案件一覧!$E$4:$E$12,--(案件一覧!$M$4:$M$12<=4)) -> 62 | G40: =前提!H$56+SUMPRODUCT($B$6:$B$14,案件一覧!$E$4:$E$12,--(案件一覧!$M$4:$M$12<=5)) -> 83 | H40: =前提!I$56+SUMPRODUCT($B$6:$B$14,案件一覧!$E$4:$E$12,--(案件一覧!$M$4:$M$12<=6)) -> 83 | I40: =前提!J$56+SUMPRODUCT($B$6:$B$14,案件一覧!$E$4:$E$12,--(案件一覧!$M$4:$M$12<=7)) -> 83 | J40: =前提!K$56+SUMPRODUCT($B$6:$B$14,案件一覧!$E$4:$E$12,--(案件一覧!$M$4:$M$12<=8)) -> 83 | K40: =前提!L$56+SUMPRODUCT($B$6:$B$14,案件一覧!$E$4:$E$12,--(案件一覧!$M$4:$M$12<=9)) -> 83 | L40: =前提!M$56+SUMPRODUCT($B$6:$B$14,案件一覧!$E$4:$E$12,--(案件一覧!$M$4:$M$12<=10)) -> 83 | M40: =前提!N$56+SUMPRODUCT($B$6:$B$14,案件一覧!$E$4:$E$12,--(案件一覧!$M$4:$M$12<=11)) -> 83 | N40: =前提!O$56+SUMPRODUCT($B$6:$B$14,案件一覧!$E$4:$E$12,--(案件一覧!$M$4:$M$12<=12)) -> 83 | O40: =前提!P$56+SUMPRODUCT($B$6:$B$14,案件一覧!$E$4:$E$12,--(案件一覧!$M$4:$M$12<=13)) -> 83 | P40: =前提!Q$56+SUMPRODUCT($B$6:$B$14,案件一覧!$E$4:$E$12,--(案件一覧!$M$4:$M$12<=14)) -> 83 | Q40: =前提!R$56+SUMPRODUCT($B$6:$B$14,案件一覧!$E$4:$E$12,--(案件一覧!$M$4:$M$12<=15)) -> 83 | R40: =前提!S$56+SUMPRODUCT($B$6:$B$14,案件一覧!$E$4:$E$12,--(案件一覧!$M$4:$M$12<=16)) -> 83
A41: 有利子負債（既存＋承継＋対象会社借入・最小化時） | C41: =前提!D$58+SUMPRODUCT($B$6:$B$14,案件一覧!$G$4:$G$12,--(案件一覧!$M$4:$M$12<=1))+IF($B$3="最小化",SUMPRODUCT($B$6:$B$14,案件一覧!$P$4:$P$12,--(案件一覧!$Q$4:$Q$12<=1)),0) -> 410 | D41: =前提!E$58+SUMPRODUCT($B$6:$B$14,案件一覧!$G$4:$G$12,--(案件一覧!$M$4:$M$12<=2))+IF($B$3="最小化",SUMPRODUCT($B$6:$B$14,案件一覧!$P$4:$P$12,--(案件一覧!$Q$4:$Q$12<=2)),0) -> 405.2 | E41: =前提!F$58+SUMPRODUCT($B$6:$B$14,案件一覧!$G$4:$G$12,--(案件一覧!$M$4:$M$12<=3))+IF($B$3="最小化",SUMPRODUCT($B$6:$B$14,案件一覧!$P$4:$P$12,--(案件一覧!$Q$4:$Q$12<=3)),0) -> 445.2 | F41: =前提!G$58+SUMPRODUCT($B$6:$B$14,案件一覧!$G$4:$G$12,--(案件一覧!$M$4:$M$12<=4))+IF($B$3="最小化",SUMPRODUCT($B$6:$B$14,案件一覧!$P$4:$P$12,--(案件一覧!$Q$4:$Q$12<=4)),0) -> 523.4 | G41: =前提!H$58+SUMPRODUCT($B$6:$B$14,案件一覧!$G$4:$G$12,--(案件一覧!$M$4:$M$12<=5))+IF($B$3="最小化",SUMPRODUCT($B$6:$B$14,案件一覧!$P$4:$P$12,--(案件一覧!$Q$4:$Q$12<=5)),0) -> 518.5 | H41: =前提!I$58+SUMPRODUCT($B$6:$B$14,案件一覧!$G$4:$G$12,--(案件一覧!$M$4:$M$12<=6))+IF($B$3="最小化",SUMPRODUCT($B$6:$B$14,案件一覧!$P$4:$P$12,--(案件一覧!$Q$4:$Q$12<=6)),0) -> 513.6 | I41: =前提!J$58+SUMPRODUCT($B$6:$B$14,案件一覧!$G$4:$G$12,--(案件一覧!$M$4:$M$12<=7))+IF($B$3="最小化",SUMPRODUCT($B$6:$B$14,案件一覧!$P$4:$P$12,--(案件一覧!$Q$4:$Q$12<=7)),0) -> 508.8 | J41: =前提!K$58+SUMPRODUCT($B$6:$B$14,案件一覧!$G$4:$G$12,--(案件一覧!$M$4:$M$12<=8))+IF($B$3="最小化",SUMPRODUCT($B$6:$B$14,案件一覧!$P$4:$P$12,--(案件一覧!$Q$4:$Q$12<=8)),0) -> 503.9 | K41: =前提!L$58+SUMPRODUCT($B$6:$B$14,案件一覧!$G$4:$G$12,--(案件一覧!$M$4:$M$12<=9))+IF($B$3="最小化",SUMPRODUCT($B$6:$B$14,案件一覧!$P$4:$P$12,--(案件一覧!$Q$4:$Q$12<=9)),0) -> 549.1 | L41: =前提!M$58+SUMPRODUCT($B$6:$B$14,案件一覧!$G$4:$G$12,--(案件一覧!$M$4:$M$12<=10))+IF($B$3="最小化",SUMPRODUCT($B$6:$B$14,案件一覧!$P$4:$P$12,--(案件一覧!$Q$4:$Q$12<=10)),0) -> 544.2 | M41: =前提!N$58+SUMPRODUCT($B$6:$B$14,案件一覧!$G$4:$G$12,--(案件一覧!$M$4:$M$12<=11))+IF($B$3="最小化",SUMPRODUCT($B$6:$B$14,案件一覧!$P$4:$P$12,--(案件一覧!$Q$4:$Q$12<=11)),0) -> 539.4 | N41: =前提!O$58+SUMPRODUCT($B$6:$B$14,案件一覧!$G$4:$G$12,--(案件一覧!$M$4:$M$12<=12))+IF($B$3="最小化",SUMPRODUCT($B$6:$B$14,案件一覧!$P$4:$P$12,--(案件一覧!$Q$4:$Q$12<=12)),0) -> 534.5 | O41: =前提!P$58+SUMPRODUCT($B$6:$B$14,案件一覧!$G$4:$G$12,--(案件一覧!$M$4:$M$12<=13))+IF($B$3="最小化",SUMPRODUCT($B$6:$B$14,案件一覧!$P$4:$P$12,--(案件一覧!$Q$4:$Q$12<=13)),0) -> 529.7 | P41: =前提!Q$58+SUMPRODUCT($B$6:$B$14,案件一覧!$G$4:$G$12,--(案件一覧!$M$4:$M$12<=14))+IF($B$3="最小化",SUMPRODUCT($B$6:$B$14,案件一覧!$P$4:$P$12,--(案件一覧!$Q$4:$Q$12<=14)),0) -> 524.9 | Q41: =前提!R$58+SUMPRODUCT($B$6:$B$14,案件一覧!$G$4:$G$12,--(案件一覧!$M$4:$M$12<=15))+IF($B$3="最小化",SUMPRODUCT($B$6:$B$14,案件一覧!$P$4:$P$12,--(案件一覧!$Q$4:$Q$12<=15)),0) -> 520 | R41: =前提!S$58+SUMPRODUCT($B$6:$B$14,案件一覧!$G$4:$G$12,--(案件一覧!$M$4:$M$12<=16))+IF($B$3="最小化",SUMPRODUCT($B$6:$B$14,案件一覧!$P$4:$P$12,--(案件一覧!$Q$4:$Q$12<=16)),0) -> 515.1
A42: Net Debt Capacity ＝ EBITDA×4＋売掛金＋現預金−有利子負債 | C42: =C40*4+C38+C39-C41 -> 315.2 | D42: =D40*4+D38+D39-D41 -> 302.9 | E42: =E40*4+E38+E39-E41 -> 421.4 | F42: =F40*4+F38+F39-F41 -> 348.2 | G42: =G40*4+G38+G39-G41 -> 436.1 | H42: =H40*4+H38+H39-H41 -> 436 | I42: =I40*4+I38+I39-I41 -> 423.8 | J42: =J40*4+J38+J39-J41 -> 423.7 | ... R42: =R40*4+R38+R39-R41 -> 372.5
A45: サマリー指標
A46: 総支出（案件・16ヶ月） | B46: =-S30 -> 253.7
...

Sheet S2
A1: S2 基本＋ワイズケア — HD単体 月次キャッシュ推移（百万円）
A2: 実行フラグ（1＝実行、0＝見送り）とモード（現行／最小化）を変えると全体が再計算されます。青字＝入力値
A3: モード | B3: 最小化 | C3: ← 「現行」または「最小化」
A5: 案件 | B5: 実行フラグ
A6: HT100%化 | B6: 1
A7: メディプロ | B7: 1
A8: ヒューマンアイ | B8: 1
A9: クレッシェンド | B9: 1
A10: ワイズケア | B10: 1
A11: エーステイスト | B11: 0
A12: 日本経営センター | B12: 0
A13: セレサ | B13: 0
A14: シルバーメディカル | B14: 1
A17: 項目 | C17: 2026/9 | D17: 2026/10 | E17: 2026/11 | F17: 2026/12 | G17: 2027/1 | H17: 2027/2 | I17: 2027/3 | J17: 2027/4 | K17: 2027/5 | L17: 2027/6 | M17: 2027/7 | N17: 2027/8 | O17: 2027/9 | P17: 2027/10 | Q17: 2027/11 | R17: 2027/12 | S17: 合計
A18: 期首現預金 | C18: =前提!$B$3 -> 366.3 | D18: =C31 -> 329.3 | E18: =D31 -> 295.4 | F18: =E31 -> 93.6 | G18: =F31 -> -39.4 | H18: =G31 -> -44.4 | I18: =H31 -> -49.4 | J18: =I31 -> -66.4 | K18: =J31 -> -71.4 | ... R18: =Q31 -> -106.4
A19: HD運営費 | C19: =前提!D$11 -> -7 | D19: =前提!E$11 -> -7 | E19: =前提!F$11 -> -7 | F19: =前提!G$11 -> -7 | G19: =前提!H$11 -> -5 | H19: =前提!I$11 -> -5 | I19: =前提!J$11 -> -5 | J19: =前提!K$11 -> -5 | ... R19: =前提!S$11 -> -5 | S19: =SUM(C19:R19) -> -88
A20: 案件支出（マイナスは対象会社借入等による軽減）
A21: HT100%化 | C21: =-$B$6*(SUMIFS(前提!$D$12:$D$51,前提!$A$12:$A$51,TRIM($A21),前提!$C$12:$C$51,"共通")+SUMIFS(前提!$D$12:$D$51,前提!$A$12:$A$51,TRIM($A21),前提!$C$12:$C$51,$B$3)) -> -30 | D21: =-$B$6*(SUMIFS(前提!$E$12:$E$51,前提!$A$12:$A$51,TRIM($A21),前提!$C$12:$C$51,"共通")+SUMIFS(前提!$E$12:$E$51,前提!$A$12:$A$51,TRIM($A21),前提!$C$12:$C$51,$B$3)) -> 0 | E21: =-$B$6*(SUMIFS(前提!$F$12:$F$51,前提!$A$12:$A$51,TRIM($A21),前提!$C$12:$C$51,"共通")+SUMIFS(前提!$F$12:$F$51,前提!$A$12:$A$51,TRIM($A21),前提!$C$12:$C$51,$B$3)) -> 0 | F21: =-$B$6*(SUMIFS(前提!$G$12:$G$51,前提!$A$12:$A$51,TRIM($A21),前提!$C$12:$C$51,"共通")+SUMIFS(前提!$G$12:$G$51,前提!$A$12:$A$51,TRIM($A21),前提!$C$12:$C$51,$B$3)) -> 0 | G21: =-$B$6*(SUMIFS(前提!$H$12:$H$51,前提!$A$12:$A$51,TRIM($A21),前提!$C$12:$C$51,"共通")+SUMIFS(前提!$H$12:$H$51,前提!$A$12:$A$51,TRIM($A21),前提!$C$12:$C$51,$B$3)) -> 0 | H21: =-$B$6*(SUMIFS(前提!$I$12:$I$51,前提!$A$12:$A$51,TRIM($A21),前提!$C$12:$C$51,"共通")+SUMIFS(前提!$I$12:$I$51,前提!$A$12:$A$51,TRIM($A21),前提!$C$12:$C$51,$B$3)) -> 0 | I21: =-$B$6*(SUMIFS(前提!$J$12:$J$51,前提!$A$12:$A$51,TRIM($A21),前提!$C$12:$C$51,"共通")+SUMIFS(前提!$J$12:$J$51,前提!$A$12:$A$51,TRIM($A21),前提!$C$12:$C$51,$B$3)) -> 0 | J21: =-$B$6*(SUMIFS(前提!$K$12:$K$51,前提!$A$12:$A$51,TRIM($A21),前提!$C$12:$C$51,"共通")+SUMIFS(前提!$K$12:$K$51,前提!$A$12:$A$51,TRIM($A21),前提!$C$12:$C$51,$B$3)) -> 0 | K21: =-$B$6*(SUMIFS(前提!$L$12:$L$51,前提!$A$12:$A$51,TRIM($A21),前提!$C$12:$C$51,"共通")+SUMIFS(前提!$L$12:$L$51,前提!$A$12:$A$51,TRIM($A21),前提!$C$12:$C$51,$B$3)) -> 0 | L21: =-$B$6*(SUMIFS(前提!$M$12:$M$51,前提!$A$12:$A$51,TRIM($A21),前提!$C$12:$C$51,"共通")+SUMIFS(前提!$M$12:$M$51,前提!$A$12:$A$51,TRIM($A21),前提!$C$12:$C$51,$B$3)) -> 0 | M21: =-$B$6*(SUMIFS(前提!$N$12:$N$51,前提!$A$12:$A$51,TRIM($A21),前提!$C$12:$C$51,"共通")+SUMIFS(前提!$N$12:$N$51,前提!$A$12:$A$51,TRIM($A21),前提!$C$12:$C$51,$B$3)) -> 0 | N21: =-$B$6*(SUMIFS(前提!$O$12:$O$51,前提!$A$12:$A$51,TRIM($A21),前提!$C$12:$C$51,"共通")+SUMIFS(前提!$O$12:$O$51,前提!$A$12:$A$51,TRIM($A21),前提!$C$12:$C$51,$B$3)) -> 0 | O21: =-$B$6*(SUMIFS(前提!$P$12:$P$51,前提!$A$12:$A$51,TRIM($A21),前提!$C$12:$C$51,"共通")+SUMIFS(前提!$P$12:$P$51,前提!$A$12:$A$51,TRIM($A21),前提!$C$12:$C$51,$B$3)) -> 0 | P21: =-$B$6*(SUMIFS(前提!$Q$12:$Q$51,前提!$A$12:$A$51,TRIM($A21),前提!$C$12:$C$51,"共通")+SUMIFS(前提!$Q$12:$Q$51,前提!$A$12:$A$51,TRIM($A21),前提!$C$12:$C$51,$B$3)) -> 0 | Q21: =-$B$6*(SUMIFS(前提!$R$12:$R$51,前提!$A$12:$A$51,TRIM($A21),前提!$C$12:$C$51,"共通")+SUMIFS(前提!$R$12:$R$51,前提!$A$12:$A$51,TRIM($A21),前提!$C$12:$C$51,$B$3)) -> 0 | R21: =-$B$6*(SUMIFS(前提!$S$12:$S$51,前提!$A$12:$A$51,TRIM($A21),前提!$C$12:$C$51,"共通")+SUMIFS(前提!$S$12:$S$51,前提!$A$12:$A$51,TRIM($A21),前提!$C$12:$C$51,$B$3)) -> 0 | S21: =SUM(C21:R21) -> -30
